Workbook

Sheet Draft
A1: Draft Sheet | B1: Bank
A10: Captain | B10: =B23 -> Elmer | C10: =C23 -> Matt | D10: =D23 -> Taran | E10: =E23 -> Leo | F10: =F23 -> Maas | G10: =G23 -> BXu | I10: Trades Made:
A11: Keeper | B11: =B23 -> Elmer | C11: =C23 -> Matt | D11: =D23 -> Taran | E11: =E23 -> Leo | F11: Hawkins | G11: JChan
A12: 1st Round | B12: 1. Nikita S | C12: 2. Porco | D12: 3. Mike H | E12: 4. Fritz | F12: 5. Grish | G12: 6. DC
A13: 2nd Round | B13: 12. Sonne | C13: 11. Marmo | D13: 10. Madams | E13: 9. Arnav | F13: 8. Rockett | G13: 7. Schmid
A14: 3rd Round | B14: 13. Crosby | C14: 14. Swit | D14: 15. Jay S | E14: 16. Lanuza | F14: 17. Du | G14: 18. Kian
A15: 4th Round | B15: 24. Emi | C15: 23. KZ | D15: 22. Tripp | E15: 21. Samos | F15: 20. Raymond | G15: 19. Hando
A16: 5th Round | B16: 25. SoHo | C16: 26. Somil | D16: 27. Lulu | E16: 28. Kyi | F16: 29. Derek | G16: 30. Petric | I16: Future Trades:
A17: 6th Round | B17: 36. Nagle | C17: 35. Suyoag | D17: 34. Ilt | E17: 33. TC | F17: 32. Neo | G17: 31. Mike Zhou
A18: 7th Round
A19: 8th Round
A21: Teams
B22: Candice? | C22: Team C | D22: Team E | E22: Migos | F22: Gargantuan | G22: Team F
A23: Captain | B23: Elmer | C23: Matt | D23: Taran | E23: Leo | F23: Maas | G23: BXu
A24: Keeper | B24: John Y | C24: Gid | D24: Miguel F | E24: Seb | F24: Hawkins | G24: JChan
A25: Pick 1 | B25: Porco | C25: Nikita S | D25: Mike H | E25: Fritz | F25: Grish | G25: DC
A26: Pick 2 | B26: Marmo | C26: Sonne | D26: Madams | E26: Arnav | F26: Rockett | G26: Schmid | H26: =B30
A27: Pick 3 | B27: Swit | C27: Crosby | D27: Jay S | E27: Lanuza | F27: Du | G27: Kian
A28: Pick 4 | B28: Emi | C28: Kevin Zhou | D28: Tripp | E28: Samos | F28: Raymond | G28: Hando
A29: Pick 5 | B29: SoHo | C29: Somil | D29: Lulu | E29: Kyi | F29: Derek | G29: Petric
A30: Pick 6 | C30: Suyoag | D30: Ilt | E30: TC | F30: Neo | G30: Mike Zhou
A31: Pick 7 | C31: Will Ho | D31: Pasha | E31: Adi | F31: Brendan | G31: Cole
A32: Pick 8 | C32: Nagle | F32: Hanono
A35: Pledge Draft | B35: Bank
A42: Teams
B43: Candice? | C43: =C22 -> Team C | D43: =D22 -> Team E | E43: Migos | F43: =F22 -> Gargantuan | G43: =G22 -> Team F
A44: Captain | B44: =B23 -> Elmer | C44: =C23 -> Matt | D44: =D23 -> Taran | E44: =E23 -> Leo | F44: =F23 -> Maas | G44: =G23 -> BXu
A46: 1 | B46: John | C46: Gid | D46: Guel | E46: Seb | F46: Hawkins | G46: JChan | H46: =7*6+12 -> 54
A47: =A46+1 -> 2 | B47: Porco | C47: Skeet | D47: Mike Harrison | E47: Fritz | F47: Grish | G47: DC
A48: =A47+1 -> 3 | B48: Marmo | C48: Sonne | D48: Madams | E48: Arnav | F48: Rockett | G48: Schmid
A49: =A48+1 -> 4 | B49: Swit | C49: Crosby | D49: Saluja | E49: Lanuza | F49: Du | G49: Kian
A50: =A49+1 -> 5 | B50: Emi | C50: Kevin Zhou | D50: Tripp | E50: Samos | F50: Raymond | G50: Hando
A51: =A50+1 -> 6 | B51: SoHo | C51: Somil | D51: Lulu | E51: Kyi | F51: Derek | G51: Petric
A52: =A51+1 -> 7 | C52: Suyoag | D52: Ilt | E52: TC | F52: Neo | G52: Mike Zhou
A53: =A52+1 -> 8 | C53: Will Ho | D53: Pasha | E53: Adi | F53: Brendan | G53: Cole
A54: =A53+1 -> 9 | C54: Nagle | F54: Hanono
A55: =A54+1 -> 10
A56: =A55+1 -> 11

Sheet General Info
A1: Example Schedule | B1: Date | D1: Bylaws
A2: Draft | B2: August 29th | E2: Members
A3: Game 1 | B3: September 1st/2nd | F3: Candice? | G3: =Draft!C22 -> Team C | H3: =Draft!D22 -> Team E | I3: Migos | J3: =Draft!F22 -> Gargantuan | K3: =Draft!G22 -> Team F
A4: Game 2 | B4: September 8th/9th | E4: Captain | F4: =Draft!B23 -> Elmer | G4: =Draft!C23 -> Matt | H4: =Draft!D23 -> Taran | I4: =Draft!E23 -> Leo | J4: =Draft!F23 -> Maas | K4: =Draft!G23 -> BXu
A5: Combine | B5: September 15th | C5: After Pinning | E5: Keeper | F5: =Draft!B24 -> John Y | G5: =Draft!C24 -> Gid | H5: =Draft!D24 -> Miguel F | I5: =Draft!E24 -> Seb | J5: =Draft!F24 -> Hawkins | K5: =Draft!G24 -> JChan
A6: Game 3 | B6: September 15th/16th | C6: Pinning/Pledge Night | E6: Pick 1 | F6: =Draft!B25 -> Porco | G6: =Draft!C25 -> Nikita S | H6: =Draft!D25 -> Mike H | I6: =Draft!E25 -> Fritz | J6: Grish | K6: =Draft!G25 -> DC
A7: Pledge Draft | B7: September 17th | E7: Pick 2 | F7: =Draft!B26 -> Marmo | G7: =Draft!C26 -> Sonne | H7: =Draft!D26 -> Madams | I7: =Draft!E26 -> Arnav | J7: =Draft!F26 -> Rockett | K7: =Draft!G26 -> Schmid
A8: Game 4 | B8: September 22nd/23rd | E8: Pick 3 | F8: =Draft!B27 -> Swit | G8: =Draft!C27 -> Crosby | H8: =Draft!D27 -> Jay S | I8: =Draft!E27 -> Lanuza | J8: =Draft!F27 -> Du | K8: =Draft!G27 -> Kian
A9: Game 5 | B9: September 29th/30th | E9: Pick 4 | F9: =Draft!B28 -> Emi | G9: =Draft!C28 -> Kevin Zhou | H9: =Draft!D28 -> Tripp | I9: =Draft!E28 -> Samos | J9: =Draft!F28 -> Raymond | K9: =Draft!G28 -> Hando
A10: Game 6 | B10: October 6th/7th | E10: Pick 5 | F10: =Draft!B29 -> SoHo | G10: =Draft!C29 -> Somil | H10: =Draft!D29 -> Lulu | I10: =Draft!E29 -> Kyi | J10: =Draft!F29 -> Derek | K10: =Draft!G29 -> Petric
A11: Bye Week | B11: October 13th | C11: Fall Break | E11: Pick 6 | F11: =Draft!B30 | G11: =Draft!C30 -> Suyoag | H11: =Draft!D30 -> Ilt | I11: =Draft!E30 -> TC | J11: =Draft!F30 -> Neo | K11: =Draft!G30 -> Mike Zhou
A12: Bye Week | B12: October 21st | C12: Fall Break | E12: Pick 7 | F12: =Draft!B31 | G12: =Draft!C31 -> Will Ho | H12: =Draft!D31 -> Pasha | I12: =Draft!E31 -> Adi | J12: =Draft!F31 -> Brendan | K12: =Draft!G31 -> Cole
A13: Game 7 | B13: October 27th/28th | E13: Pick 8 | F13: =Draft!B32 | G13: =Draft!C32 -> Nagle | H13: =Draft!D32 | I13: =Draft!E32 | J13: =Draft!F32 -> Hanono | K13: =Draft!G32
A14: Semifinals (1) | B14: November 3rd/4th | C14: Game 1 | E14: Pledge 1
A15: Semifinals (2/3) | B15: November 10th/11th | C15: Game 2/3 | E15: Pledge 2
A16: Finals | B16: November 17th/18th | E16: Pledge 3
E17: Pledge 4
A18: Thanksgiving | B18: November 24th | E18: Pledge 5
A19: If Season Delayed | B19: December 1st
A20: Last Possible Game | B20: December 8th

Sheet Team Stats
A1: =Draft!B23 -> Elmer | G1: =Draft!D23 -> Taran
A2: =Draft!B22 -> Candice? | B2: Opponent | C2: Home/Away | D2: Result | E2: Margin | G2: =Draft!D22 -> Team E | H2: Opponent | I2: Home/Away | J2: Result | K2: Margin
A3: Game 1 | B3: =VLOOKUP(A2, 'Full Schedule'!$A$3:$B$9, 2, False) -> Team F | C3: Home | D3: =if('Week 1'!$A$1=A2, 'Week 1'!$E$1, if('Week 1'!$J$1=A2, 'Week 1'!$N$1, if('Week 1'!$A$21=A2, 'Week 1'!$E$21, if('Week 1'!$J$21=A2, 'Week 1'!$N$21, if('Week 1'!$A$41=A2, 'Week 1'!$E$41, if('Week 1'!$J$41=A2, 'Week 1'!$N$41)))))) -> Loss | E3: =if('Week 1'!$A$1=A2, 'Week 1'!$H$1, if('Week 1'!$J$1=A2, 'Week 1'!$Q$1, if('Week 1'!$A$21=A2, 'Week 1'!$H$21, if('Week 1'!$J$21=A2, 'Week 1'!$Q$21, if('Week 1'!$A$41=A2, 'Week 1'!$H$41, if('Week 1'!$J$41=A2, 'Week 1'!$Q$41)))))) -> -1 | G3: Game 1 | H3: =VLOOKUP(G2, 'Full Schedule'!$A$3:$B$9, 2, False) -> Team C | I3: Home | J3: =if('Week 1'!$A$1=G2, 'Week 1'!$E$1, if('Week 1'!$J$1=G2, 'Week 1'!$N$1, if('Week 1'!$A$21=G2, 'Week 1'!$E$21, if('Week 1'!$J$21=G2, 'Week 1'!$N$21, if('Week 1'!$A$41=G2, 'Week 1'!$E$41, if('Week 1'!$J$41=G2, 'Week 1'!$N$41)))))) -> Loss | K3: =if('Week 1'!$A$1=G2, 'Week 1'!$H$1, if('Week 1'!$J$1=G2, 'Week 1'!$Q$1, if('Week 1'!$A$21=G2, 'Week 1'!$H$21, if('Week 1'!$J$21=G2, 'Week 1'!$Q$21, if('Week 1'!$A$41=G2, 'Week 1'!$H$41, if('Week 1'!$J$41=G2, 'Week 1'!$Q$41)))))) -> -20
A4: Game 2 | B4: =vlookup(A2, 'Full Schedule'!$C$3:$D$8, 2, False) -> Gargantuan | C4: Away | D4: =if('Week 2'!$A$1=A2, 'Week 2'!$E$1, if('Week 2'!$J$1=A2, 'Week 1'!$N$1, if('Week 2'!$A$21=A2, 'Week 2'!$E$21, if('Week 2'!$J$21=A2, 'Week 2'!$N$21, if('Week 2'!$A$41=A2, 'Week 2'!$E$41, if('Week 2'!$J$41=A2, 'Week 2'!$N$41)))))) -> Win | E4: =if('Week 2'!$A$1=A2, 'Week 2'!$H$1, if('Week 2'!$J$1=A2, 'Week 2'!$Q$1, if('Week 2'!$A$21=A2, 'Week 2'!$H$21, if('Week 2'!$J$21=A2, 'Week 2'!$Q$21, if('Week 2'!$A$41=A2, 'Week 2'!$H$41, if('Week 2'!$J$41=A2, 'Week 2'!$Q$41)))))) -> 0 | G4: Game 2 | H4: =vlookup(G2, 'Full Schedule'!$C$3:$D$8, 2, False) -> Team F | I4: Away | J4: =if('Week 2'!$A$1=G2, 'Week 2'!$E$1, if('Week 2'!$J$1=G2, 'Week 1'!$N$1, if('Week 2'!$A$21=G2, 'Week 2'!$E$21, if('Week 2'!$J$21=G2, 'Week 2'!$N$21, if('Week 2'!$A$41=G2, 'Week 2'!$E$41, if('Week 2'!$J$41=G2, 'Week 2'!$N$41)))))) -> Loss | K4: =if('Week 2'!$A$1=G2, 'Week 2'!$H$1, if('Week 2'!$J$1=G2, 'Week 2'!$Q$1, if('Week 2'!$A$21=G2, 'Week 2'!$H$21, if('Week 2'!$J$21=G2, 'Week 2'!$Q$21, if('Week 2'!$A$41=G2, 'Week 2'!$H$41, if('Week 2'!$J$41=G2, 'Week 2'!$Q$41)))))) -> -15
A5: Game 3 | B5: =vlookup(A2, 'Full Schedule'!$E$3:$F$8, 2, False) -> Migos | C5: Away | D5: =if('Week 3'!$A$1=A2, 'Week 3'!$E$1, if('Week 3'!$J$1=A2, 'Week 3'!$N$1, if('Week 3'!$A$21=A2, 'Week 3'!$E$21, if('Week 3'!$J$21=A2, 'Week 3'!$N$21, if('Week 3'!$A$41=A2, 'Week 3'!$E$41, if('Week 3'!$J$41=A2, 'Week 3'!$N$41)))))) -> Win | E5: =if('Week 3'!$A$1=A2, 'Week 3'!$H$1, if('Week 3'!$J$1=A2, 'Week 3'!$Q$1, if('Week 3'!$A$21=A2, 'Week 3'!$H$21, if('Week 3'!$J$21=A2, 'Week 3'!$Q$21, if('Week 3'!$A$41=A2, 'Week 3'!$H$41, if('Week 3'!$J$41=A2, 'Week 3'!$Q$41)))))) -> 4 | G5: Game 3 | H5: =vlookup(G2, 'Full Schedule'!$E$3:$F$8, 2, False) -> Team F | I5: Home | J5: =if('Week 3'!$A$1=G2, 'Week 3'!$E$1, if('Week 3'!$J$1=G2, 'Week 3'!$N$1, if('Week 3'!$A$21=G2, 'Week 3'!$E$21, if('Week 3'!$J$21=G2, 'Week 3'!$N$21, if('Week 3'!$A$41=G2, 'Week 3'!$E$41, if('Week 3'!$J$41=G2, 'Week 3'!$N$41)))))) -> Loss | K5: =if('Week 3'!$A$1=G2, 'Week 3'!$H$1, if('Week 3'!$J$1=G2, 'Week 3'!$Q$1, if('Week 3'!$A$21=G2, 'Week 3'!$H$21, if('Week 3'!$J$21=G2, 'Week 3'!$Q$21, if('Week 3'!$A$41=G2, 'Week 3'!$H$41, if('Week 3'!$J$41=G2, 'Week 3'!$Q$41)))))) -> -7 | M5: West
A6: Game 4 | B6: =vlookup(A2, 'Full Schedule'!$G$3:$H$8, 2, False) -> Team E | C6: Home | D6: =if('Week 4'!$A$1=A2, 'Week 4'!$E$1, if('Week 4'!$J$1=A2, 'Week 4'!$N$1, if('Week 4'!$A$21=A2, 'Week 4'!$E$21, if('Week 4'!$J$21=A2, 'Week 4'!$N$21, if('Week 4'!$A$41=A2, 'Week 4'!$E$41, if('Week 4'!$J$41=A2, 'Week 4'!$N$41)))))) -> Win | E6: =if('Week 4'!$A$1=A2, 'Week 4'!$H$1, if('Week 4'!$J$1=A2, 'Week 4'!$Q$1, if('Week 4'!$A$21=A2, 'Week 4'!$H$21, if('Week 4'!$J$21=A2, 'Week 4'!$Q$21, if('Week 4'!$A$41=A2, 'Week 4'!$H$41, if('Week 4'!$J$41=A2, 'Week 4'!$Q$41)))))) -> 5 | G6: Game 4 | H6: =vlookup(G2, 'Full Schedule'!$G$3:$H$8, 2, False) -> Candice? | I6: Away | J6: =if('Week 4'!$A$1=G2, 'Week 4'!$E$1, if('Week 4'!$J$1=G2, 'Week 4'!$N$1, if('Week 4'!$A$21=G2, 'Week 4'!$E$21, if('Week 4'!$J$21=G2, 'Week 4'!$N$21, if('Week 4'!$A$41=G2, 'Week 4'!$E$41, if('Week 4'!$J$41=G2, 'Week 4'!$N$41)))))) -> Loss | K6: =if('Week 4'!$A$1=G2, 'Week 4'!$H$1, if('Week 4'!$J$1=G2, 'Week 4'!$Q$1, if('Week 4'!$A$21=G2, 'Week 4'!$H$21, if('Week 4'!$J$21=G2, 'Week 4'!$Q$21, if('Week 4'!$A$41=G2, 'Week 4'!$H$41, if('Week 4'!$J$41=G2, 'Week 4'!$Q$41)))))) -> -5 | N6: Win % | O6: Margin
A7: Game 5 | B7: =vlookup(A2, 'Full Schedule'!$I$3:$J$8, 2, False) -> Gargantuan | C7: Away | D7: =if('Week 5'!$A$1=A2, 'Week 5'!$E$1, if('Week 5'!$J$1=A2, 'Week 5'!$N$1, if('Week 5'!$A$21=A2, 'Week 5'!$E$21, if('Week 5'!$J$21=A2, 'Week 5'!$N$21, if('Week 5'!$A$41=A2, 'Week 5'!$E$41, if('Week 5'!$J$41=A2, 'Week 5'!$N$41)))))) -> Loss | E7: =if('Week 5'!$A$1=A2, 'Week 5'!$H$1, if('Week 5'!$J$1=A2, 'Week 5'!$Q$1, if('Week 5'!$A$21=A2, 'Week 5'!$H$21, if('Week 5'!$J$21=A2, 'Week 5'!$Q$21, if('Week 5'!$A$41=A2, 'Week 5'!$H$41, if('Week 5'!$J$41=A2, 'Week 5'!$Q$41)))))) -> -11 | G7: Game 5 | H7: =vlookup(G2, 'Full Schedule'!$I$3:$J$8, 2, False) -> Team C | I7: Home | J7: =if('Week 5'!$A$1=G2, 'Week 5'!$E$1, if('Week 5'!$J$1=G2, 'Week 5'!$N$1, if('Week 5'!$A$21=G2, 'Week 5'!$E$21, if('Week 5'!$J$21=G2, 'Week 5'!$N$21, if('Week 5'!$A$41=G2, 'Week 5'!$E$41, if('Week 5'!$J$41=G2, 'Week 5'!$N$41)))))) -> Loss | K7: =if('Week 5'!$A$1=G2, 'Week 5'!$H$1, if('Week 5'!$J$1=G2, 'Week 5'!$Q$1, if('Week 5'!$A$21=G2, 'Week 5'!$H$21, if('Week 5'!$J$21=G2, 'Week 5'!$Q$21, if('Week 5'!$A$41=G2, 'Week 5'!$H$41, if('Week 5'!$J$41=G2, 'Week 5'!$Q$41)))))) -> -23 | M7: =Draft!B22 -> Candice? | N7: =if($M7=$A$2, D$12, if($M7=$G$2, J$12, if($M7=$A$15, D$25, if($M7=$G$15, J$25, if($M7=$A$28, D$38, if($M7=$G$28, J$38)))))) -> 0.57142857 | O7: =if($M7=$A$2, E$12, if($M7=$G$2, K$12, if($M7=$A$15, E$25, if($M7=$G$15, K$25, if($M7=$A$28, E$38, if($M7=$G$28, K$38)))))) -> -8
A8: Game 6 | B8: =vlookup(A2, 'Full Schedule'!$K$3:$L$8, 2, False) -> Migos | C8: Home | D8: =if('Week 6'!$A$1=A2, 'Week 6'!$E$1, if('Week 6'!$J$1=A2, 'Week 6'!$N$1, if('Week 6'!$A$21=A2, 'Week 6'!$E$21, if('Week 6'!$J$21=A2, 'Week 6'!$N$21, if('Week 6'!$A$41=A2, 'Week 6'!$E$41, if('Week 6'!J$41=A2, 'Week 6'!$N$41)))))) -> Loss | E8: =if('Week 6'!$A$1=A2, 'Week 6'!$H$1, if('Week 6'!$J$1=A2, 'Week 6'!$Q$1, if('Week 6'!$A$21=A2, 'Week 6'!$H$21, if('Week 6'!$J$21=A2, 'Week 6'!$Q$21, if('Week 6'!$A$41=A2, 'Week 6'!$H$41, if('Week 6'!$J$41=A2, 'Week 6'!$Q$41)))))) -> -6 | G8: Game 6 | H8: =vlookup(G2, 'Full Schedule'!$K$3:$L$8, 2, False) -> Gargantuan | I8: Away | J8: =if('Week 6'!$A$1=G2, 'Week 6'!$E$1, if('Week 6'!$J$1=G2, 'Week 6'!$N$1, if('Week 6'!$A$21=G2, 'Week 6'!$E$21, if('Week 6'!$J$21=G2, 'Week 6'!$N$21, if('Week 6'!$A$41=G2, 'Week 6'!$E$41, if('Week 6'!$J$41=G2, 'Week 6'!$N$41)))))) -> Win | K8: =if('Week 6'!$A$1=G2, 'Week 6'!$H$1, if('Week 6'!$J$1=G2, 'Week 6'!$Q$1, if('Week 6'!$A$21=G2, 'Week 6'!$H$21, if('Week 6'!$J$21=G2, 'Week 6'!$Q$21, if('Week 6'!$A$41=G2, 'Week 6'!$H$41, if('Week 6'!$J$41=G2, 'Week 6'!$Q$41)))))) -> 4 | M8: =Draft!E22 -> Migos | N8: =if($M8=$A$2, D$12, if($M8=$G$2, J$12, if($M8=$A$15, D$25, if($M8=$G$15, J$25, if($M8=$A$28, D$38, if($M8=$G$28, J$38)))))) -> 0.71428571 | O8: =if($M8=$A$2, E$12, if($M8=$G$2, K$12, if($M8=$A$15, E$25, if($M8=$G$15, K$25, if($M8=$A$28, E$38, if($M8=$G$28, K$38)))))) -> 26.5
A9: Game 7 | B9: =vlookup(A2, 'Full Schedule'!$M$3:$N$8, 2, False) -> Team C | C9: Split | D9: =if('Week 7'!$A$1=A2, 'Week 7'!$E1, if('Week 7'!$J$1=A2, 'Week 7'!$N$1, if('Week 7'!$A$21=A2, 'Week 7'!$E$21, if('Week 7'!$J$21=A2, 'Week 7'!$N$21, if('Week 7'!$A$41=A2, 'Week 7'!$E$41, if('Week 7'!$J$41=A2, 'Week 7'!$N$41)))))) -> Win | E9: =if('Week 7'!$A$1=A2, 'Week 7'!$H$1, if('Week 7'!$J$1=A2, 'Week 7'!$Q$1, if('Week 7'!$A$21=A2, 'Week 7'!$H$21, if('Week 7'!$J$21=A2, 'Week 7'!$Q$21, if('Week 7'!$A$41=A2, 'Week 7'!$H$41, if('Week 7'!$J$41=A2, 'Week 7'!$Q$41)))))) -> 1 | G9: Game 7 | H9: =vlookup(G2, 'Full Schedule'!$M$3:$N$8, 2, False) -> Migos | I9: Split | J9: =if('Week 7'!$A$1=G2, 'Week 7'!$E1, if('Week 7'!$J$1=G2, 'Week 7'!$N$1, if('Week 7'!$A$21=G2, 'Week 7'!$E$21, if('Week 7'!$J$21=G2, 'Week 7'!$N$21, if('Week 7'!$A$41=G2, 'Week 7'!$E$41, if('Week 7'!$J$41=G2, 'Week 7'!$N$41)))))) -> Win | K9: =if('Week 7'!$A$1=G2, 'Week 7'!$H$1, if('Week 7'!$J$1=G2, 'Week 7'!$Q$1, if('Week 7'!$A$21=G2, 'Week 7'!$H$21, if('Week 7'!$J$21=G2, 'Week 7'!$Q$21, if('Week 7'!$A$41=G2, 'Week 7'!$H$41, if('Week 7'!$J$41=G2, 'Week 7'!$Q$41)))))) -> 0.5 | M9: =Draft!G22 -> Team F | N9: =if($M9=$A$2, D$12, if($M9=$G$2, J$12, if($M9=$A$15, D$25, if($M9=$G$15, J$25, if($M9=$A$28, D$38, if($M9=$G$28, J$38)))))) -> 0.71428571 | O9: =if($M9=$A$2, E$12, if($M9=$G$2, K$12, if($M9=$A$15, E$25, if($M9=$G$15, K$25, if($M9=$A$28, E$38, if($M9=$G$28, K$38)))))) -> 20
M11: East
A12: Total | D12: =countif(D3:D9, "Win")/(countif(D3:D9, "Win")+countif(D3:D9, "Loss")) -> 0.57142857 | E12: =SUM(E3:E11) -> -8 | G12: Total | J12: =countif(J3:J9, "Win")/(countif(J3:J9, "Win")+countif(J3:J9, "Loss")) -> 0.28571429 | K12: =SUM(K3:K11) -> -65.5 | N12: Win % | O12: Margin
M13: =Draft!C22 -> Team C | N13: =if($M13=$A$2, D$12, if($M13=$G$2, J$12, if($M13=$A$15, D$25, if($M13=$G$15, J$25, if($M13=$A$28, D$38, if($M13=$G$28, J$38)))))) -> 0.57142857 | O13: =if($M13=$A$2, E$12, if($M13=$G$2, K$12, if($M13=$A$15, E$25, if($M13=$G$15, K$25, if($M13=$A$28, E$38, if($M13=$G$28, K$38)))))) -> 64
A14: =Draft!C23 -> Matt | G14: =Draft!E23 -> Leo | M14: =Draft!D22 -> Team E | N14: =if($M14=$A$2, D$12, if($M14=$G$2, J$12, if($M14=$A$15, D$25, if($M14=$G$15, J$25, if($M14=$A$28, D$38, if($M14=$G$28, J$38)))))) -> 0.28571429 | O14: =if($M14=$A$2, E$12, if($M14=$G$2, K$12, if($M14=$A$15, E$25, if($M14=$G$15, K$25, if($M14=$A$28, E$38, if($M14=$G$28, K$38)))))) -> -65.5
A15: =Draft!C22 -> Team C | B15: Opponent | C15: Home/Away | D15: Result | E15: Margin | G15: =Draft!E22 -> Migos | H15: Opponent | I15: Home/Away | J15: Result | K15: Margin | M15: =Draft!F22 -> Gargantuan | N15: =if($M15=$A$2, D$12, if($M15=$G$2, J$12, if($M15=$A$15, D$25, if($M15=$G$15, J$25, if($M15=$A$28, D$38, if($M15=$G$28, J$38)))))) -> 0.14285714 | O15: =if($M15=$A$2, E$12, if($M15=$G$2, K$12, if($M15=$A$15, E$25, if($M15=$G$15, K$25, if($M15=$A$28, E$38, if($M15=$G$28, K$38)))))) -> -37
A16: Game 1 | B16: =VLOOKUP(A15, 'Full Schedule'!$A$3:$B$9, 2, False) -> Team E | C16: Away | D16: =if('Week 1'!$A$1=A15, 'Week 1'!$E$1, if('Week 1'!$J$1=A15, 'Week 1'!$N$1, if('Week 1'!$A$21=A15, 'Week 1'!$E$21, if('Week 1'!$J$21=A15, 'Week 1'!$N$21, if('Week 1'!$A$41=A15, 'Week 1'!$E$41, if('Week 1'!$J$41=A15, 'Week 1'!$N$41)))))) -> Win | E16: =if('Week 1'!$A$1=A15, 'Week 1'!$H$1, if('Week 1'!$J$1=A15, 'Week 1'!$Q$1, if('Week 1'!$A$21=A15, 'Week 1'!$H$21, if('Week 1'!$J$21=A15, 'Week 1'!$Q$21, if('Week 1'!$A$41=A15, 'Week 1'!$H$41, if('Week 1'!$J$41=A15, 'Week 1'!$Q$41)))))) -> 20 | G16: Game 1 | H16: =VLOOKUP(G15, 'Full Schedule'!$A$3:$B$9, 2, False) -> Gargantuan | I16: Away | J16: =if('Week 1'!$A$1=G15, 'Week 1'!$E$1, if('Week 1'!$J$1=G15, 'Week 1'!$N$1, if('Week 1'!$A$21=G15, 'Week 1'!$E$21, if('Week 1'!$J$21=G15, 'Week 1'!$N$21, if('Week 1'!$A$41=G15, 'Week 1'!$E$41, if('Week 1'!$J$41=G15, 'Week 1'!$N$41)))))) -> Win | K16: =if('Week 1'!$A$1=G15, 'Week 1'!$H$1, if('Week 1'!$J$1=G15, 'Week 1'!$Q$1, if('Week 1'!$A$21=G15, 'Week 1'!$H$21, if('Week 1'!$J$21=G15, 'Week 1'!$Q$21, if('Week 1'!$A$41=G15, 'Week 1'!$H$41, if('Week 1'!$J$41=G15, 'Week 1'!$Q$41)))))) -> 5
A17: Game 2 | B17: =vlookup(A15, 'Full Schedule'!$C$3:$D$8, 2, False) -> Migos | C17: Home | D17: =if('Week 2'!$A$1=A15, 'Week 2'!$E$1, if('Week 2'!$J$1=A15, 'Week 1'!$N$1, if('Week 2'!$A$21=A15, 'Week 2'!$E$21, if('Week 2'!$J$21=A15, 'Week 2'!$N$21, if('Week 2'!$A$41=A15, 'Week 2'!$E$41, if('Week 2'!$J$41=A15, 'Week 2'!$N$41)))))) -> Loss | E17: =if('Week 2'!$A$1=A15, 'Week 2'!$H$1, if('Week 2'!$J$1=A15, 'Week 2'!$Q$1, if('Week 2'!$A$21=A15, 'Week 2'!$H$21, if('Week 2'!$J$21=A15, 'Week 2'!$Q$21, if('Week 2'!$A$41=A15, 'Week 2'!$H$41, if('Week 2'!$J$41=A15, 'Week 2'!$Q$41)))))) -> -10 | G17: Game 2 | H17: =vlookup(G15, 'Full Schedule'!$C$3:$D$8, 2, False) -> Team C | I17: Away | J17: =if('Week 2'!$A$1=G15, 'Week 2'!$E$1, if('Week 2'!$J$1=G15, 'Week 1'!$N$1, if('Week 2'!$A$21=G15, 'Week 2'!$E$21, if('Week 2'!$J$21=G15, 'Week 2'!$N$21, if('Week 2'!$A$41=G15, 'Week 2'!$E$41, if('Week 2'!$J$41=G15, 'Week 2'!$N$41)))))) -> Win | K17: =if('Week 2'!$A$1=G15, 'Week 2'!$H$1, if('Week 2'!$J$1=G15, 'Week 2'!$Q$1, if('Week 2'!$A$21=G15, 'Week 2'!$H$21, if('Week 2'!$J$21=G15, 'Week 2'!$Q$21, if('Week 2'!$A$41=G15, 'Week 2'!$H$41, if('Week 2'!$J$41=G15, 'Week 2'!$Q$41)))))) -> 10
A18: Game 3 | B18: =vlookup(A15, 'Full Schedule'!$E$3:$F$8, 2, False) -> Gargantuan | C18: Home | D18: =if('Week 3'!$A$1=A15, 'Week 3'!$E$1, if('Week 3'!$J$1=A15, 'Week 3'!$N$1, if('Week 3'!$A$21=A15, 'Week 3'!$E$21, if('Week 3'!$J$21=A15, 'Week 3'!$N$21, if('Week 3'!$A$41=A15, 'Week 3'!$E$41, if('Week 3'!$J$41=A15, 'Week 3'!$N$41)))))) -> Win | E18: =if('Week 3'!$A$1=A15, 'Week 3'!$H$1, if('Week 3'!$J$1=A15, 'Week 3'!$Q$1, if('Week 3'!$A$21=A15, 'Week 3'!$H$21, if('Week 3'!$J$21=A15, 'Week 3'!$Q$21, if('Week 3'!$A$41=A15, 'Week 3'!$H$41, if('Week 3'!$J$41=A15, 'Week 3'!$Q$41)))))) -> 26 | G18: Game 3 | H18: =vlookup(G15, 'Full Schedule'!$E$3:$F$8, 2, False) -> Candice? | I18: Home | J18: =if('Week 3'!$A$1=G15, 'Week 3'!$E$1, if('Week 3'!$J$1=G15, 'Week 3'!$N$1, if('Week 3'!$A$21=G15, 'Week 3'!$E$21, if('Week 3'!$J$21=G15, 'Week 3'!$N$21, if('Week 3'!$A$41=G15, 'Week 3'!$E$41, if('Week 3'!$J$41=G15, 'Week 3'!$N$41)))))) -> Loss | K18: =if('Week 3'!$A$1=G15, 'Week 3'!$H$1, if('Week 3'!$J$1=G15, 'Week 3'!$Q$1, if('Week 3'!$A$21=G15, 'Week 3'!$H$21, if('Week 3'!$J$21=G15, 'Week 3'!$Q$21, if('Week 3'!$A$41=G15, 'Week 3'!$H$41, if('Week 3'!$J$41=G15, 'Week 3'!$Q$41)))))) -> -4
A19: Game 4 | B19: =vlookup(A15, 'Full Schedule'!$G$3:$H$8, 2, False) -> Team F | C19: Away | D19: =if('Week 4'!$A$1=A15, 'Week 4'!$E$1, if('Week 4'!$J$1=A15, 'Week 4'!$N$1, if('Week 4'!$A$21=A15, 'Week 4'!$E$21, if('Week 4'!$J$21=A15, 'Week 4'!$N$21, if('Week 4'!$A$41=A15, 'Week 4'!$E$41, if('Week 4'!$J$41=A15, 'Week 4'!$N$41)))))) -> Win | E19: =if('Week 4'!$A$1=A15, 'Week 4'!$H$1, if('Week 4'!$J$1=A15, 'Week 4'!$Q$1, if('Week 4'!$A$21=A15, 'Week 4'!$H$21, if('Week 4'!$J$21=A15, 'Week 4'!$Q$21, if('Week 4'!$A$41=A15, 'Week 4'!$H$41, if('Week 4'!$J$41=A15, 'Week 4'!$Q$41)))))) -> 9 | G19: Game 4 | H19: =vlookup(G15, 'Full Schedule'!$G$3:$H$8, 2, False) -> Gargantuan | I19: Away | J19: =if('Week 4'!$A$1=G15, 'Week 4'!$E$1, if('Week 4'!$J$1=G15, 'Week 4'!$N$1, if('Week 4'!$A$21=G15, 'Week 4'!$E$21, if('Week 4'!$J$21=G15, 'Week 4'!$N$21, if('Week 4'!$A$41=G15, 'Week 4'!$E$41, if('Week 4'!$J$41=G15, 'Week 4'!$N$41)))))) -> Win | K19: =if('Week 4'!$A$1=G15, 'Week 4'!$H$1, if('Week 4'!$J$1=G15, 'Week 4'!$Q$1, if('Week 4'!$A$21=G15, 'Week 4'!$H$21, if('Week 4'!$J$21=G15, 'Week 4'!$Q$21, if('Week 4'!$A$41=G15, 'Week 4'!$H$41, if('Week 4'!$J$41=G15, 'Week 4'!$Q$41)))))) -> 9
A20: Game 5 | B20: =vlookup(A15, 'Full Schedule'!$I$3:$J$8, 2, False) -> Team E | C20: Home | D20: =if('Week 5'!$A$1=A15, 'Week 5'!$E$1, if('Week 5'!$J$1=A15, 'Week 5'!$N$1, if('Week 5'!$A$21=A15, 'Week 5'!$E$21, if('Week 5'!$J$21=A15, 'Week 5'!$N$21, if('Week 5'!$A$41=A15, 'Week 5'!$E$41, if('Week 5'!$J$41=A15, 'Week 5'!$N$41)))))) -> Win | E20: =if('Week 5'!$A$1=A15, 'Week 5'!$H$1, if('Week 5'!$J$1=A15, 'Week 5'!$Q$1, if('Week 5'!$A$21=A15, 'Week 5'!$H$21, if('Week 5'!$J$21=A15, 'Week 5'!$Q$21, if('Week 5'!$A$41=A15, 'Week 5'!$H$41, if('Week 5'!$J$41=A15, 'Week 5'!$Q$41)))))) -> 23 | G20: Game 5 | H20: =vlookup(G15, 'Full Schedule'!$I$3:$J$8, 2, False) -> Team F | I20: Home | J20: =if('Week 5'!$A$1=G15, 'Week 5'!$E$1, if('Week 5'!$J$1=G15, 'Week 5'!$N$1, if('Week 5'!$A$21=G15, 'Week 5'!$E$21, if('Week 5'!$J$21=G15, 'Week 5'!$N$21, if('Week 5'!$A$41=G15, 'Week 5'!$E$41, if('Week 5'!$J$41=G15, 'Week 5'!$N$41)))))) -> Win | K20: =if('Week 5'!$A$1=G15, 'Week 5'!$H$1, if('Week 5'!$J$1=G15, 'Week 5'!$Q$1, if('Week 5'!$A$21=G15, 'Week 5'!$H$21, if('Week 5'!$J$21=G15, 'Week 5'!$Q$21, if('Week 5'!$A$41=G15, 'Week 5'!$H$41, if('Week 5'!$J$41=G15, 'Week 5'!$Q$41)))))) -> 1
A21: Game 6 | B21: =vlookup(A15, 'Full Schedule'!$K$3:$L$8, 2, False) -> Team F | C21: Away | D21: =if('Week 6'!$A$1=A15, 'Week 6'!$E$1, if('Week 6'!$J$1=A15, 'Week 6'!$N$1, if('Week 6'!$A$21=A15, 'Week 6'!$E$21, if('Week 6'!$J$21=A15, 'Week 6'!$N$21, if('Week 6'!$A$41=A15, 'Week 6'!$E$41, if('Week 6'!J$41=A15, 'Week 6'!$N$41)))))) -> Loss | E21: =if('Week 6'!$A$1=A15, 'Week 6'!$H$1, if('Week 6'!$J$1=A15, 'Week 6'!$Q$1, if('Week 6'!$A$21=A15, 'Week 6'!$H$21, if('Week 6'!$J$21=A15, 'Week 6'!$Q$21, if('Week 6'!$A$41=A15, 'Week 6'!$H$41, if('Week 6'!$J$41=A15, 'Week 6'!$Q$41)))))) -> -3 | G21: Game 6 | H21: =vlookup(G15, 'Full Schedule'!$K$3:$L$8, 2, False) -> Candice? | I21: Home | J21: =if('Week 6'!$A$1=G15, 'Week 6'!$E$1, if('Week 6'!$J$1=G15, 'Week 6'!$N$1, if('Week 6'!$A$21=G15, 'Week 6'!$E$21, if('Week 6'!$J$21=G15, 'Week 6'!$N$21, if('Week 6'!$A$41=G15, 'Week 6'!$E$41, if('Week 6'!$J$41=G15, 'Week 6'!$N$41)))))) -> Win | K21: =if('Week 6'!$A$1=G15, 'Week 6'!$H$1, if('Week 6'!$J$1=G15, 'Week 6'!$Q$1, if('Week 6'!$A$21=G15, 'Week 6'!$H$21, if('Week 6'!$J$21=G15, 'Week 6'!$Q$21, if('Week 6'!$A$41=G15, 'Week 6'!$H$41, if('Week 6'!$J$41=G15, 'Week 6'!$Q$41)))))) -> 6
A22: Game 7 | B22: =vlookup(A15, 'Full Schedule'!$M$3:$N$8, 2, False) -> Candice? | C22: Split | D22: =if('Week 7'!$A$1=A15, 'Week 7'!$E14, if('Week 7'!$J$1=A15, 'Week 7'!$N$1, if('Week 7'!$A$21=A15, 'Week 7'!$E$21, if('Week 7'!$J$21=A15, 'Week 7'!$N$21, if('Week 7'!$A$41=A15, 'Week 7'!$E$41, if('Week 7'!$J$41=A15, 'Week 7'!$N$41)))))) -> Loss | E22: =if('Week 7'!$A$1=A15, 'Week 7'!$H$1, if('Week 7'!$J$1=A15, 'Week 7'!$Q$1, if('Week 7'!$A$21=A15, 'Week 7'!$H$21, if('Week 7'!$J$21=A15, 'Week 7'!$Q$21, if('Week 7'!$A$41=A15, 'Week 7'!$H$41, if('Week 7'!$J$41=A15, 'Week 7'!$Q$41)))))) -> -1 | G22: Game 7 | H22: =vlookup(G15, 'Full Schedule'!$M$3:$N$8, 2, False) -> Team E | I22: Split | J22: =if('Week 7'!$A$1=G15, 'Week 7'!$E14, if('Week 7'!$J$1=G15, 'Week 7'!$N$1, if('Week 7'!$A$21=G15, 'Week 7'!$E$21, if('Week 7'!$J$21=G15, 'Week 7'!$N$21, if('Week 7'!$A$41=G15, 'Week 7'!$E$41, if('Week 7'!$J$41=G15, 'Week 7'!$N$41)))))) -> Loss | K22: =if('Week 7'!$A$1=G15, 'Week 7'!$H$1, if('Week 7'!$J$1=G15, 'Week 7'!$Q$1, if('Week 7'!$A$21=G15, 'Week 7'!$H$21, if('Week 7'!$J$21=G15, 'Week 7'!$Q$21, if('Week 7'!$A$41=G15, 'Week 7'!$H$41, if('Week 7'!$J$41=G15, 'Week 7'!$Q$41)))))) -> -0.5
A25: Total | D25: =countif(D16:D22, "Win")/(countif(D16:D22, "Win")+countif(D16:D22, "Loss")) -> 0.57142857 | E25: =SUM(E16:E24) -> 64 | G25: Total | J25: =countif(J16:J22, "Win")/(countif(J16:J22, "Win")+countif(J16:J22, "Loss")) -> 0.71428571 | K25: =SUM(K16:K24) -> 26.5
A27: =Draft!F23 -> Maas | G27: =Draft!G23 -> BXu
A28: =Draft!F22 -> Gargantuan | B28: Opponent | C28: Home/Away | D28: Result | E28: Margin | G28: =Draft!G22 -> Team F | H28: Opponent | I28: Home/Away | J28: Result | K28: Margin
A29: Game 1 | B29: =VLOOKUP(A28, 'Full Schedule'!$A$3:$B$9, 2, False) -> Migos | C29: Away | D29: =if('Week 1'!$A$1=A28, 'Week 1'!$E$1, if('Week 1'!$J$1=A28, 'Week 1'!$N$1, if('Week 1'!$A$21=A28, 'Week 1'!$E$21, if('Week 1'!$J$21=A28, 'Week 1'!$N$21, if('Week 1'!$A$41=A28, 'Week 1'!$E$41, if('Week 1'!$J$41=A28, 'Week 1'!$N$41)))))) -> Loss | E29: =if('Week 1'!$A$1=A28, 'Week 1'!$H$1, if('Week 1'!$J$1=A28, 'Week 1'!$Q$1, if('Week 1'!$A$21=A28, 'Week 1'!$H$21, if('Week 1'!$J$21=A28, 'Week 1'!$Q$21, if('Week 1'!$A$41=A28, 'Week 1'!$H$41, if('Week 1'!$J$41=A28, 'Week 1'!$Q$41)))))) -> -5 | G29: Game 1 | H29: =VLOOKUP(G28, 'Full Schedule'!$A$3:$B$9, 2, False) -> Candice? | I29: Home | J29: =if('Week 1'!$A$1=G28, 'Week 1'!$E$1, if('Week 1'!$J$1=G28, 'Week 1'!$N$1, if('Week 1'!$A$21=G28, 'Week 1'!$E$21, if('Week 1'!$J$21=G28, 'Week 1'!$N$21, if('Week 1'!$A$41=G28, 'Week 1'!$E$41, if('Week 1'!$J$41=G28, 'Week 1'!$N$41)))))) -> Win | K29: =if('Week 1'!$A$1=G28, 'Week 1'!$H$1, if('Week 1'!$J$1=G28, 'Week 1'!$Q$1, if('Week 1'!$A$21=G28, 'Week 1'!$H$21, if('Week 1'!$J$21=G28, 'Week 1'!$Q$21, if('Week 1'!$A$41=G28, 'Week 1'!$H$41, if('Week 1'!$J$41=G28, 'Week 1'!$Q$41)))))) -> 1
A30: Game 2 | B30: =vlookup(A28, 'Full Schedule'!$C$3:$D$8, 2, False) -> Candice? | C30: Home | D30: =if('Week 2'!$A$1=A28, 'Week 2'!$E$1, if('Week 2'!$J$1=A28, 'Week 1'!$N$1, if('Week 2'!$A$21=A28, 'Week 2'!$E$21, if('Week 2'!$J$21=A28, 'Week 2'!$N$21, if('Week 2'!$A$41=A28, 'Week 2'!$E$41, if('Week 2'!$J$41=A28, 'Week 2'!$N$41)))))) -> Loss | E30: =if('Week 2'!$A$1=A28, 'Week 2'!$H$1, if('Week 2'!$J$1=A28, 'Week 2'!$Q$1, if('Week 2'!$A$21=A28, 'Week 2'!$H$21, if('Week 2'!$J$21=A28, 'Week 2'!$Q$21, if('Week 2'!$A$41=A28, 'Week 2'!$H$41, if('Week 2'!$J$41=A28, 'Week 2'!$Q$41)))))) -> 0 | G30: Game 2 | H30: =vlookup(G28, 'Full Schedule'!$C$3:$D$8, 2, False) -> Team E | I30: Home | J30: =if('Week 2'!$A$1=G28, 'Week 2'!$E$1, if('Week 2'!$J$1=G28, 'Week 1'!$N$1, if('Week 2'!$A$21=G28, 'Week 2'!$E$21, if('Week 2'!$J$21=G28, 'Week 2'!$N$21, if('Week 2'!$A$41=G28, 'Week 2'!$E$41, if('Week 2'!$J$41=G28, 'Week 2'!$N$41)))))) -> Win | K30: =if('Week 2'!$A$1=G28, 'Week 2'!$H$1, if('Week 2'!$J$1=G28, 'Week 2'!$Q$1, if('Week 2'!$A$21=G28, 'Week 2'!$H$21, if('Week 2'!$J$21=G28, 'Week 2'!$Q$21, if('Week 2'!$A$41=G28, 'Week 2'!$H$41, if('Week 2'!$J$41=G28, 'Week 2'!$Q$41)))))) -> 15
A31: Game 3 | B31: =vlookup(A28, 'Full Schedule'!$E$3:$F$8, 2, False) -> Team C | C31: Away | D31: =if('Week 3'!$A$1=A28, 'Week 3'!$E$1, if('Week 3'!$J$1=A28, 'Week 3'!$N$1, if('Week 3'!$A$21=A28, 'Week 3'!$E$21, if('Week 3'!$J$21=A28, 'Week 3'!$N$21, if('Week 3'!$A$41=A28, 'Week 3'!$E$41, if('Week 3'!$J$41=A28, 'Week 3'!$N$41)))))) -> Loss | E31: =if('Week 3'!$A$1=A28, 'Week 3'!$H$1, if('Week 3'!$J$1=A28, 'Week 3'!$Q$1, if('Week 3'!$A$21=A28, 'Week 3'!$H$21, if('Week 3'!$J$21=A28, 'Week 3'!$Q$21, if('Week 3'!$A$41=A28, 'Week 3'!$H$41, if('Week 3'!$J$41=A28, 'Week 3'!$Q$41)))))) -> -26 | G31: Game 3 | H31: =vlookup(G28, 'Full Schedule'!$E$3:$F$8, 2, False) -> Team E | I31: Away | J31: =if('Week 3'!$A$1=G28, 'Week 3'!$E$1, if('Week 3'!$J$1=G28, 'Week 3'!$N$1, if('Week 3'!$A$21=G28, 'Week 3'!$E$21, if('Week 3'!$J$21=G28, 'Week 3'!$N$21, if('Week 3'!$A$41=G28, 'Week 3'!$E$41, if('Week 3'!$J$41=G28, 'Week 3'!$N$41)))))) -> Win | K31: =if('Week 3'!$A$1=G28, 'Week 3'!$H$1, if('Week 3'!$J$1=G28, 'Week 3'!$Q$1, if('Week 3'!$A$21=G28, 'Week 3'!$H$21, if('Week 3'!$J$21=G28, 'Week 3'!$Q$21, if('Week 3'!$A$41=G28, 'Week 3'!$H$41, if('Week 3'!$J$41=G28, 'Week 3'!$Q$41)))))) -> 7
A32: Game 4 | B32: =vlookup(A28, 'Full Schedule'!$G$3:$H$8, 2, False) -> Migos | C32: Home | D32: =if('Week 4'!$A$1=A28, 'Week 4'!$E$1, if('Week 4'!$J$1=A28, 'Week 4'!$N$1, if('Week 4'!$A$21=A28, 'Week 4'!$E$21, if('Week 4'!$J$21=A28, 'Week 4'!$N$21, if('Week 4'!$A$41=A28, 'Week 4'!$E$41, if('Week 4'!$J$41=A28, 'Week 4'!$N$41)))))) -> Loss | E32: =if('Week 4'!$A$1=A28, 'Week 4'!$H$1, if('Week 4'!$J$1=A28, 'Week 4'!$Q$1, if('Week 4'!$A$21=A28, 'Week 4'!$H$21, if('Week 4'!$J$21=A28, 'Week 4'!$Q$21, if('Week 4'!$A$41=A28, 'Week 4'!$H$41, if('Week 4'!$J$41=A28, 'Week 4'!$Q$41)))))) -> -9 | G32: Game 4 | H32: =vlookup(G28, 'Full Schedule'!$G$3:$H$8, 2, False) -> Team C | I32: Home | J32: =if('Week 4'!$A$1=G28, 'Week 4'!$E$1, if('Week 4'!$J$1=G28, 'Week 4'!$N$1, if('Week 4'!$A$21=G28, 'Week 4'!$E$21, if('Week 4'!$J$21=G28, 'Week 4'!$N$21, if('Week 4'!$A$41=G28, 'Week 4'!$E$41, if('Week 4'!$J$41=G28, 'Week 4'!$N$41)))))) -> Loss | K32: =if('Week 4'!$A$1=G28, 'Week 4'!$H$1, if('Week 4'!$J$1=G28, 'Week 4'!$Q$1, if('Week 4'!$A$21=G28, 'Week 4'!$H$21, if('Week 4'!$J$21=G28, 'Week 4'!$Q$21, if('Week 4'!$A$41=G28, 'Week 4'!$H$41, if('Week 4'!$J$41=G28, 'Week 4'!$Q$41)))))) -> -9
A33: Game 5 | B33: =vlookup(A28, 'Full Schedule'!$I$3:$J$8, 2, False) -> Candice? | C33: Away | D33: =if('Week 5'!$A$1=A28, 'Week 5'!$E$1, if('Week 5'!$J$1=A28, 'Week 5'!$N$1, if('Week 5'!$A$21=A28, 'Week 5'!$E$21, if('Week 5'!$J$21=A28, 'Week 5'!$N$21, if('Week 5'!$A$41=A28, 'Week 5'!$E$41, if('Week 5'!$J$41=A28, 'Week 5'!$N$41)))))) -> Win | E33: =if('Week 5'!$A$1=A28, 'Week 5'!$H$1, if('Week 5'!$J$1=A28, 'Week 5'!$Q$1, if('Week 5'!$A$21=A28, 'Week 5'!$H$21, if('Week 5'!$J$21=A28, 'Week 5'!$Q$21, if('Week 5'!$A$41=A28, 'Week 5'!$H$41, if('Week 5'!$J$41=A28, 'Week 5'!$Q$41)))))) -> 11 | G33: Game 5 | H33: =vlookup(G28, 'Full Schedule'!$I$3:$J$8, 2, False) -> Migos | I33: Away | J33: =if('Week 5'!$A$1=G28, 'Week 5'!$E$1, if('Week 5'!$J$1=G28, 'Week 5'!$N$1, if('Week 5'!$A$21=G28, 'Week 5'!$E$21, if('Week 5'!$J$21=G28, 'Week 5'!$N$21, if('Week 5'!$A$41=G28, 'Week 5'!$E$41, if('Week 5'!$J$41=G28, 'Week 5'!$N$41)))))) -> Loss | K33: =if('Week 5'!$A$1=G28, 'Week 5'!$H$1, if('Week 5'!$J$1=G28, 'Week 5'!$Q$1, if('Week 5'!$A$21=G28, 'Week 5'!$H$21, if('Week 5'!$J$21=G28, 'Week 5'!$Q$21, if('Week 5'!$A$41=G28, 'Week 5'!$H$41, if('Week 5'!$J$41=G28, 'Week 5'!$Q$41)))))) -> -1
A34: Game 6 | B34: =vlookup(A28, 'Full Schedule'!$K$3:$L$8, 2, False) -> Team E | C34: Home | D34: =if('Week 6'!$A$1=A28, 'Week 6'!$E$1, if('Week 6'!$J$1=A28, 'Week 6'!$N$1, if('Week 6'!$A$21=A28, 'Week 6'!$E$21, if('Week 6'!$J$21=A28, 'Week 6'!$N$21, if('Week 6'!$A$41=A28, 'Week 6'!$E$41, if('Week 6'!J$41=A28, 'Week 6'!$N$41)))))) -> Loss | E34: =if('Week 6'!$A$1=A28, 'Week 6'!$H$1, if('Week 6'!$J$1=A28, 'Week 6'!$Q$1, if('Week 6'!$A$21=A28, 'Week 6'!$H$21, if('Week 6'!$J$21=A28, 'Week 6'!$Q$21, if('Week 6'!$A$41=A28, 'Week 6'!$H$41, if('Week 6'!$J$41=A28, 'Week 6'!$Q$41)))))) -> -4 | G34: Game 6 | H34: =vlookup(G28, 'Full Schedule'!$K$3:$L$8, 2, False) -> Team C | I34: Away | J34: =if('Week 6'!$A$1=G28, 'Week 6'!$E$1, if('Week 6'!$J$1=G28, 'Week 6'!$N$1, if('Week 6'!$A$21=G28, 'Week 6'!$E$21, if('Week 6'!$J$21=G28, 'Week 6'!$N$21, if('Week 6'!$A$41=G28, 'Week 6'!$E$41, if('Week 6'!$J$41=G28, 'Week 6'!$N$41)))))) -> Win | K34: =if('Week 6'!$A$1=G28, 'Week 6'!$H$1, if('Week 6'!$J$1=G28, 'Week 6'!$Q$1, if('Week 6'!$A$21=G28, 'Week 6'!$H$21, if('Week 6'!$J$21=G28, 'Week 6'!$Q$21, if('Week 6'!$A$41=G28, 'Week 6'!$H$41, if('Week 6'!$J$41=G28, 'Week 6'!$Q$41)))))) -> 3
A35: Game 7 | B35: =vlookup(A28, 'Full Schedule'!$M$3:$N$8, 2, False) -> Team F | C35: Split | D35: =if('Week 7'!$A$1=A28, 'Week 7'!$E27, if('Week 7'!$J$1=A28, 'Week 7'!$N$1, if('Week 7'!$A$21=A28, 'Week 7'!$E$21, if('Week 7'!$J$21=A28, 'Week 7'!$N$21, if('Week 7'!$A$41=A28, 'Week 7'!$E$41, if('Week 7'!$J$41=A28, 'Week 7'!$N$41)))))) -> Loss | E35: =if('Week 7'!$A$1=A28, 'Week 7'!$H$1, if('Week 7'!$J$1=A28, 'Week 7'!$Q$1, if('Week 7'!$A$21=A28, 'Week 7'!$H$21, if('Week 7'!$J$21=A28, 'Week 7'!$Q$21, if('Week 7'!$A$41=A28, 'Week 7'!$H$41, if('Week 7'!$J$41=A28, 'Week 7'!$Q$41)))))) -> -4 | G35: Game 7 | H35: =vlookup(G28, 'Full Schedule'!$M$3:$N$8, 2, False) -> Gargantuan | I35: Split | J35: =if('Week 7'!$A$1=G28, 'Week 7'!$E27, if('Week 7'!$J$1=G28, 'Week 7'!$N$1, if('Week 7'!$A$21=G28, 'Week 7'!$E$21, if('Week 7'!$J$21=G28, 'Week 7'!$N$21, if('Week 7'!$A$41=G28, 'Week 7'!$E$41, if('Week 7'!$J$41=G28, 'Week 7'!$N$41)))))) -> Win | K35: =if('Week 7'!$A$1=G28, 'Week 7'!$H$1, if('Week 7'!$J$1=G28, 'Week 7'!$Q$1, if('Week 7'!$A$21=G28, 'Week 7'!$H$21, if('Week 7'!$J$21=G28, 'Week 7'!$Q$21, if('Week 7'!$A$41=G28, 'Week 7'!$H$41, if('Week 7'!$J$41=G28, 'Week 7'!$Q$41)))))) -> 4
A38: Total | D38: =countif(D29:D35, "Win")/(countif(D29:D35, "Win")+countif(D29:D35, "Loss")) -> 0.14285714 | E38: =SUM(E29:E37) -> -37 | G38: Total | J38: =countif(J29:J35, "Win")/(countif(J29:J35, "Win")+countif(J29:J35, "Loss")) -> 0.71428571 | K38: =SUM(K29:K37) -> 20

Sheet Full Schedule
A1: Home | B1: Away | C1: Home | D1: Away | E1: Home | F1: Away | G1: Home | H1: Away | I1: Home | J1: Away | K1: Home | L1: Away | M1: Home | N1: Away
A2: Week 1 | C2: Week 2 | E2: Week 3 | G2: Week 4 | I2: Week 5 | K2: Week 6 | M2: Week 7
A3: Candice? | B3: Team F | C3: Gargantuan | D3: Candice? | E3: Candice? | F3: Migos | G3: Team E | H3: Candice? | I3: Candice? | J3: Gargantuan | K3: Migos | L3: Candice? | M3: Candice? | N3: Team C
A4: Team C | B4: Team E | C4: Team E | D4: Team F | E4: Team F | F4: Team E | G4: Team C | H4: Team F | I4: Team E | J4: Team C | K4: Gargantuan | L4: Team E | M4: Team E | N4: Migos
A5: Migos | B5: Gargantuan | C5: Migos | D5: Team C | E5: Team C | F5: Gargantuan | G5: Gargantuan | H5: Migos | I5: Team F | J5: Migos | K5: Team F | L5: Team C | M5: Gargantuan | N5: Team F
A6: =B3 -> Team F | B6: =A3 -> Candice? | C6: =D3 -> Candice? | D6: =C3 -> Gargantuan | E6: =F3 -> Migos | F6: =E3 -> Candice? | G6: =H3 -> Candice? | H6: =G3 -> Team E | I6: =J3 -> Gargantuan | J6: =I3 -> Candice? | K6: =L3 -> Candice? | L6: =K3 -> Migos | M6: =N3 -> Team C | N6: =M3 -> Candice?
A7: =B4 -> Team E | B7: =A4 -> Team C | C7: =D4 -> Team F | D7: =C4 -> Team E | E7: =F4 -> Team E | F7: =E4 -> Team F | G7: =H4 -> Team F | H7: =G4 -> Team C | I7: =J4 -> Team C | J7: =I4 -> Team E | K7: =L4 -> Team E | L7: =K4 -> Gargantuan | M7: =N4 -> Migos | N7: =M4 -> Team E
A8: =B5 -> Gargantuan | B8: =A5 -> Migos | C8: =D5 -> Team C | D8: =C5 -> Migos | E8: =F5 -> Gargantuan | F8: =E5 -> Team C | G8: =H5 -> Migos | H8: =G5 -> Gargantuan | I8: =J5 -> Migos | J8: =I5 -> Team F | K8: =L5 -> Team C | L8: =K5 -> Team F | M8: =N5 -> Team F | N8: =M5 -> Gargantuan

Sheet Player Season Stats
A1: Name | B1: Games Played | C1: Win % | D1: Adjusted FGM | E1: FGM | F1: Bottom | G1: Bottom ISO | H1: Top | I1: Top ISO | J1: Misses | K1: FG% | M1: Player Rating
A2: =Draft!B44 -> Elmer | B2: =iferror(vlookup($A2, 'Player Game Stats'!$A:$J, 2, False), "") -> 7 | C2: =iferror(vlookup($A2, 'Player Game Stats'!$A:$J, 3, False), "") -> 0.42857143 | D2: =iferror(1.2*I2+1.1*H2+1.05*G2+1*F2, "") -> 15.107143 | E2: =iferror(vlookup($A2, 'Player Game Stats'!$A:$J, 4, False), "") -> 14.142857 | F2: =iferror(vlookup($A2, 'Player Game Stats'!$A:$J, 5, False), "") -> 5.2857143 | G2: =iferror(vlookup($A2, 'Player Game Stats'!$A:$J, 6, False), "") -> 1 | H2: =iferror(vlookup($A2, 'Player Game Stats'!$A:$J, 7, False), "") -> 6.5714286 | I2: =IFERROR(vlookup($A2, 'Player Game Stats'!$A:$J, 8, False), "") -> 1.2857143 | J2: =iferror(vlookup($A2, 'Player Game Stats'!$A:$J, 9, False), "") -> 26.571429 | K2: =iferror(vlookup($A2, 'Player Game Stats'!$A:$J, 10, False), "") -> 0.34736842 | L2: =K2*D2 -> 5.2477444 | M2: =iferror(L2*$L$75, "") -> 14.148508
A3: =Draft!B46 -> John | B3: =iferror(vlookup($A3, 'Player Game Stats'!$A:$J, 2, False), "") -> 0 | C3: =iferror(vlookup($A3, 'Player Game Stats'!$A:$J, 3, False), "") | D3: =iferror(1.2*I3+1.1*H3+1.05*G3+1*F3, "") -> 0 | E3: =iferror(vlookup($A3, 'Player Game Stats'!$A:$J, 4, False), "") | F3: =iferror(vlookup($A3, 'Player Game Stats'!$A:$J, 5, False), "") | G3: =iferror(vlookup($A3, 'Player Game Stats'!$A:$J, 6, False), "") | H3: =iferror(vlookup($A3, 'Player Game Stats'!$A:$J, 7, False), "") | I3: =IFERROR(vlookup($A3, 'Player Game Stats'!$A:$J, 8, False), "") | J3: =iferror(vlookup($A3, 'Player Game Stats'!$A:$J, 9, False), "") | K3: =iferror(vlookup($A3, 'Player Game Stats'!$A:$J, 10, False), "") | L3: =K3*D3 -> 0 | M3: =iferror(L3*$L$75, "") -> 0
A4: =Draft!B47 -> Porco | B4: =iferror(vlookup($A4, 'Player Game Stats'!$A:$J, 2, False), "") -> 5 | C4: =iferror(vlookup($A4, 'Player Game Stats'!$A:$J, 3, False), "") -> 0.4 | D4: =iferror(1.2*I4+1.1*H4+1.05*G4+1*F4, "") -> 19.28 | E4: =iferror(vlookup($A4, 'Player Game Stats'!$A:$J, 4, False), "") -> 18 | F4: =iferror(vlookup($A4, 'Player Game Stats'!$A:$J, 5, False), "") -> 6.4 | G4: =iferror(vlookup($A4, 'Player Game Stats'!$A:$J, 6, False), "") -> 0.8 | H4: =iferror(vlookup($A4, 'Player Game Stats'!$A:$J, 7, False), "") -> 9.2 | I4: =IFERROR(vlookup($A4, 'Player Game Stats'!$A:$J, 8, False), "") -> 1.6 | J4: =iferror(vlookup($A4, 'Player Game Stats'!$A:$J, 9, False), "") -> 25.6 | K4: =iferror(vlookup($A4, 'Player Game Stats'!$A:$J, 10, False), "") -> 0.41284404 | L4: =K4*D4 -> 7.959633 | M4: =iferror(L4*$L$75, "") -> 21.460065
A5: =Draft!B48 -> Marmo | B5: =iferror(vlookup($A5, 'Player Game Stats'!$A:$J, 2, False), "") -> 7 | C5: =iferror(vlookup($A5, 'Player Game Stats'!$A:$J, 3, False), "") -> 0.42857143 | D5: =iferror(1.2*I5+1.1*H5+1.05*G5+1*F5, "") -> 18.828571 | E5: =iferror(vlookup($A5, 'Player Game Stats'!$A:$J, 4, False), "") -> 18.571429 | F5: =iferror(vlookup($A5, 'Player Game Stats'!$A:$J, 5, False), "") -> 15.857143 | G5: =iferror(vlookup($A5, 'Player Game Stats'!$A:$J, 6, False), "") -> 0.57142857 | H5: =iferror(vlookup($A5, 'Player Game Stats'!$A:$J, 7, False), "") -> 2 | I5: =IFERROR(vlookup($A5, 'Player Game Stats'!$A:$J, 8, False), "") -> 0.14285714 | J5: =iferror(vlookup($A5, 'Player Game Stats'!$A:$J, 9, False), "") -> 25.571429 | K5: =iferror(vlookup($A5, 'Player Game Stats'!$A:$J, 10, False), "") -> 0.42071197 | L5: =K5*D5 -> 7.9214055 | M5: =iferror(L5*$L$75, "") -> 21.356999
A6: =Draft!B49 -> Swit | B6: =iferror(vlookup($A6, 'Player Game Stats'!$A:$J, 2, False), "") -> 7 | C6: =iferror(vlookup($A6, 'Player Game Stats'!$A:$J, 3, False), "") -> 0.42857143 | D6: =iferror(1.2*I6+1.1*H6+1.05*G6+1*F6, "") -> 13.378571 | E6: =iferror(vlookup($A6, 'Player Game Stats'!$A:$J, 4, False), "") -> 12.571429 | F6: =iferror(vlookup($A6, 'Player Game Stats'!$A:$J, 5, False), "") -> 4.4285714 | G6: =iferror(vlookup($A6, 'Player Game Stats'!$A:$J, 6, False), "") -> 0.42857143 | H6: =iferror(vlookup($A6, 'Player Game Stats'!$A:$J, 7, False), "") -> 7.5714286 | I6: =IFERROR(vlookup($A6, 'Player Game Stats'!$A:$J, 8, False), "") -> 0.14285714 | J6: =iferror(vlookup($A6, 'Player Game Stats'!$A:$J, 9, False), "") -> 26 | K6: =iferror(vlookup($A6, 'Player Game Stats'!$A:$J, 10, False), "") -> 0.32592593 | L6: =K6*D6 -> 4.3604233 | M6: =iferror(L6*$L$75, "") -> 11.756191
A7: =Draft!B50 -> Emi | B7: =iferror(vlookup($A7, 'Player Game Stats'!$A:$J, 2, False), "") -> 6 | C7: =iferror(vlookup($A7, 'Player Game Stats'!$A:$J, 3, False), "") -> 0.5 | D7: =iferror(1.2*I7+1.1*H7+1.05*G7+1*F7, "") -> 19.4 | E7: =iferror(vlookup($A7, 'Player Game Stats'!$A:$J, 4, False), "") -> 18.666667 | F7: =iferror(vlookup($A7, 'Player Game Stats'!$A:$J, 5, False), "") -> 12 | G7: =iferror(vlookup($A7, 'Player Game Stats'!$A:$J, 6, False), "") -> 0.66666667 | H7: =iferror(vlookup($A7, 'Player Game Stats'!$A:$J, 7, False), "") -> 5 | I7: =IFERROR(vlookup($A7, 'Player Game Stats'!$A:$J, 8, False), "") -> 1 | J7: =iferror(vlookup($A7, 'Player Game Stats'!$A:$J, 9, False), "") -> 24.666667 | K7: =iferror(vlookup($A7, 'Player Game Stats'!$A:$J, 10, False), "") -> 0.43076923 | L7: =K7*D7 -> 8.3569231 | M7: =iferror(L7*$L$75, "") -> 22.531203
A8: =Draft!B51 -> SoHo | B8: =iferror(vlookup($A8, 'Player Game Stats'!$A:$J, 2, False), "") -> 4 | C8: =iferror(vlookup($A8, 'Player Game Stats'!$A:$J, 3, False), "") -> 0.5 | D8: =iferror(1.2*I8+1.1*H8+1.05*G8+1*F8, "") -> 17.5875 | E8: =iferror(vlookup($A8, 'Player Game Stats'!$A:$J, 4, False), "") -> 16.5 | F8: =iferror(vlookup($A8, 'Player Game Stats'!$A:$J, 5, False), "") -> 5.25 | G8: =iferror(vlookup($A8, 'Player Game Stats'!$A:$J, 6, False), "") -> 0.75 | H8: =iferror(vlookup($A8, 'Player Game Stats'!$A:$J, 7, False), "") -> 10.5 | I8: =IFERROR(vlookup($A8, 'Player Game Stats'!$A:$J, 8, False), "") -> 0 | J8: =iferror(vlookup($A8, 'Player Game Stats'!$A:$J, 9, False), "") -> 27.75 | K8: =iferror(vlookup($A8, 'Player Game Stats'!$A:$J, 10, False), "") -> 0.37288136 | L8: =K8*D8 -> 6.5580508 | M8: =iferror(L8*$L$75, "") -> 17.681242
A9: =Draft!B52 | B9: =iferror(vlookup($A9, 'Player Game Stats'!$A:$J, 2, False), "") | C9: =iferror(vlookup($A9, 'Player Game Stats'!$A:$J, 3, False), "") | D9: =iferror(1.2*I9+1.1*H9+1.05*G9+1*F9, "") -> 0 | E9: =iferror(vlookup($A9, 'Player Game Stats'!$A:$J, 4, False), "") | F9: =iferror(vlookup($A9, 'Player Game Stats'!$A:$J, 5, False), "") | G9: =iferror(vlookup($A9, 'Player Game Stats'!$A:$J, 6, False), "") | H9: =iferror(vlookup($A9, 'Player Game Stats'!$A:$J, 7, False), "") | I9: =IFERROR(vlookup($A9, 'Player Game Stats'!$A:$J, 8, False), "") | J9: =iferror(vlookup($A9, 'Player Game Stats'!$A:$J, 9, False), "") | K9: =iferror(vlookup($A9, 'Player Game Stats'!$A:$J, 10, False), "") | L9: =K9*D9 -> 0 | M9: =iferror(L9*$L$75, "") -> 0
A10: =Draft!B53 | B10: =iferror(vlookup($A10, 'Player Game Stats'!$A:$J, 2, False), "") | C10: =iferror(vlookup($A10, 'Player Game Stats'!$A:$J, 3, False), "") | D10: =iferror(1.2*I10+1.1*H10+1.05*G10+1*F10, "") -> 0 | E10: =iferror(vlookup($A10, 'Player Game Stats'!$A:$J, 4, False), "") | F10: =iferror(vlookup($A10, 'Player Game Stats'!$A:$J, 5, False), "") | G10: =iferror(vlookup($A10, 'Player Game Stats'!$A:$J, 6, False), "") | H10: =iferror(vlookup($A10, 'Player Game Stats'!$A:$J, 7, False), "") | I10: =IFERROR(vlookup($A10, 'Player Game Stats'!$A:$J, 8, False), "") | J10: =iferror(vlookup($A10, 'Player Game Stats'!$A:$J, 9, False), "") | K10: =iferror(vlookup($A10, 'Player Game Stats'!$A:$J, 10, False), "") | L10: =K10*D10 -> 0 | M10: =iferror(L10*$L$75, "") -> 0
A11: =Draft!B54 | B11: =iferror(vlookup($A11, 'Player Game Stats'!$A:$J, 2, False), "") | C11: =iferror(vlookup($A11, 'Player Game Stats'!$A:$J, 3, False), "") | D11: =iferror(1.2*I11+1.1*H11+1.05*G11+1*F11, "") -> 0 | E11: =iferror(vlookup($A11, 'Player Game Stats'!$A:$J, 4, False), "") | F11: =iferror(vlookup($A11, 'Player Game Stats'!$A:$J, 5, False), "") | G11: =iferror(vlookup($A11, 'Player Game Stats'!$A:$J, 6, False), "") | H11: =iferror(vlookup($A11, 'Player Game Stats'!$A:$J, 7, False), "") | I11: =IFERROR(vlookup($A11, 'Player Game Stats'!$A:$J, 8, False), "") | J11: =iferror(vlookup($A11, 'Player Game Stats'!$A:$J, 9, False), "") | K11: =iferror(vlookup($A11, 'Player Game Stats'!$A:$J, 10, False), "") | L11: =K11*D11 -> 0 | M11: =iferror(L11*$L$75, "") -> 0
A12: =Draft!B55 | B12: =iferror(vlookup($A12, 'Player Game Stats'!$A:$J, 2, False), "") | C12: =iferror(vlookup($A12, 'Player Game Stats'!$A:$J, 3, False), "") | D12: =iferror(1.2*I12+1.1*H12+1.05*G12+1*F12, "") -> 0 | E12: =iferror(vlookup($A12, 'Player Game Stats'!$A:$J, 4, False), "") | F12: =iferror(vlookup($A12, 'Player Game Stats'!$A:$J, 5, False), "") | G12: =iferror(vlookup($A12, 'Player Game Stats'!$A:$J, 6, False), "") | H12: =iferror(vlookup($A12, 'Player Game Stats'!$A:$J, 7, False), "") | I12: =IFERROR(vlookup($A12, 'Player Game Stats'!$A:$J, 8, False), "") | J12: =iferror(vlookup($A12, 'Player Game Stats'!$A:$J, 9, False), "") | K12: =iferror(vlookup($A12, 'Player Game Stats'!$A:$J, 10, False), "") | L12: =K12*D12 -> 0 | M12: =iferror(L12*$L$75, "") -> 0
A13: =Draft!B56 | B13: =iferror(vlookup($A13, 'Player Game Stats'!$A:$J, 2, False), "") | C13: =iferror(vlookup($A13, 'Player Game Stats'!$A:$J, 3, False), "") | D13: =iferror(1.2*I13+1.1*H13+1.05*G13+1*F13, "") -> 0 | E13: =iferror(vlookup($A13, 'Player Game Stats'!$A:$J, 4, False), "") | F13: =iferror(vlookup($A13, 'Player Game Stats'!$A:$J, 5, False), "") | G13: =iferror(vlookup($A13, 'Player Game Stats'!$A:$J, 6, False), "") | H13: =iferror(vlookup($A13, 'Player Game Stats'!$A:$J, 7, False), "") | I13: =IFERROR(vlookup($A13, 'Player Game Stats'!$A:$J, 8, False), "") | J13: =iferror(vlookup($A13, 'Player Game Stats'!$A:$J, 9, False), "") | K13: =iferror(vlookup($A13, 'Player Game Stats'!$A:$J, 10, False), "") | L13: =K13*D13 -> 0 | M13: =iferror(L13*$L$75, "") -> 0
A14: =Draft!C44 -> Matt | B14: =iferror(vlookup($A14, 'Player Game Stats'!$K:$T, 2, False), "") -> 7 | C14: =iferror(vlookup($A14, 'Player Game Stats'!$K:$T, 3, False), "") -> 0.57142857 | D14: =iferror(1.2*I14+1.1*H14+1.05*G14+1*F14, "") -> 16.064286 | E14: =iferror(vlookup($A14, 'Player Game Stats'!$K:$T, 4, False), "") -> 15.285714 | F14: =iferror(vlookup($A14, 'Player Game Stats'!$K:$T, 5, False), "") -> 7.5714286 | G14: =iferror(vlookup($A14, 'Player Game Stats'!$K:$T, 6, False), "") -> 1.5714286 | H14: =iferror(vlookup($A14, 'Player Game Stats'!$K:$T, 7, False), "") -> 5.2857143 | I14: =iferror(vlookup($A14, 'Player Game Stats'!$K:$T, 8, False), "") -> 0.85714286 | J14: =iferror(vlookup($A14, 'Player Game Stats'!$K:$T, 9, False), "") -> 23.714286 | K14: =iferror(vlookup($A14, 'Player Game Stats'!$K:$T, 10, False), "") -> 0.39194139 | L14: =K14*D14 -> 6.2962585 | M14: =iferror(L14*$L$75, "") -> 16.97542
A15: =Draft!C46 -> Gid | B15: =iferror(vlookup($A15, 'Player Game Stats'!$K:$T, 2, False), "") -> 7 | C15: =iferror(vlookup($A15, 'Player Game Stats'!$K:$T, 3, False), "") -> 0.57142857 | D15: =iferror(1.2*I15+1.1*H15+1.05*G15+1*F15, "") -> 20.278571 | E15: =iferror(vlookup($A15, 'Player Game Stats'!$K:$T, 4, False), "") -> 19.285714 | F15: =iferror(vlookup($A15, 'Player Game Stats'!$K:$T, 5, False), "") -> 9.4285714 | G15: =iferror(vlookup($A15, 'Player Game Stats'!$K:$T, 6, False), "") -> 2.1428571 | H15: =iferror(vlookup($A15, 'Player Game Stats'!$K:$T, 7, False), "") -> 6.5714286 | I15: =iferror(vlookup($A15, 'Player Game Stats'!$K:$T, 8, False), "") -> 1.1428571 | J15: =iferror(vlookup($A15, 'Player Game Stats'!$K:$T, 9, False), "") -> 22.857143 | K15: =iferror(vlookup($A15, 'Player Game Stats'!$K:$T, 10, False), "") -> 0.45762712 | L15: =K15*D15 -> 9.2800242 | M15: =iferror(L15*$L$75, "") -> 25.019988
A16: =Draft!C47 -> Skeet | B16: =iferror(vlookup($A16, 'Player Game Stats'!$K:$T, 2, False), "") -> 0 | C16: =iferror(vlookup($A16, 'Player Game Stats'!$K:$T, 3, False), "") | D16: =iferror(1.2*I16+1.1*H16+1.05*G16+1*F16, "") -> 0 | E16: =iferror(vlookup($A16, 'Player Game Stats'!$K:$T, 4, False), "") | F16: =iferror(vlookup($A16, 'Player Game Stats'!$K:$T, 5, False), "") | G16: =iferror(vlookup($A16, 'Player Game Stats'!$K:$T, 6, False), "") | H16: =iferror(vlookup($A16, 'Player Game Stats'!$K:$T, 7, False), "") | I16: =iferror(vlookup($A16, 'Player Game Stats'!$K:$T, 8, False), "") | J16: =iferror(vlookup($A16, 'Player Game Stats'!$K:$T, 9, False), "") | K16: =iferror(vlookup($A16, 'Player Game Stats'!$K:$T, 10, False), "") | L16: =K16*D16 -> 0 | M16: =iferror(L16*$L$75, "") -> 0
A17: =Draft!C48 -> Sonne | B17: =iferror(vlookup($A17, 'Player Game Stats'!$K:$T, 2, False), "") -> 4 | C17: =iferror(vlookup($A17, 'Player Game Stats'!$K:$T, 3, False), "") -> 0.75 | D17: =iferror(1.2*I17+1.1*H17+1.05*G17+1*F17, "") -> 13.15 | E17: =iferror(vlookup($A17, 'Player Game Stats'!$K:$T, 4, False), "") -> 12.5 | F17: =iferror(vlookup($A17, 'Player Game Stats'!$K:$T, 5, False), "") -> 7 | G17: =iferror(vlookup($A17, 'Player Game Stats'!$K:$T, 6, False), "") -> 0 | H17: =iferror(vlookup($A17, 'Player Game Stats'!$K:$T, 7, False), "") -> 4.5 | I17: =iferror(vlookup($A17, 'Player Game Stats'!$K:$T, 8, False), "") -> 1 | J17: =iferror(vlookup($A17, 'Player Game Stats'!$K:$T, 9, False), "") -> 25.25 | K17: =iferror(vlookup($A17, 'Player Game Stats'!$K:$T, 10, False), "") -> 0.33112583 | L17: =K17*D17 -> 4.3543046 | M17: =iferror(L17*$L$75, "") -> 11.739694
A18: =Draft!C49 -> Crosby | B18: =iferror(vlookup($A18, 'Player Game Stats'!$K:$T, 2, False), "") -> 5 | C18: =iferror(vlookup($A18, 'Player Game Stats'!$K:$T, 3, False), "") -> 0.6 | D18: =iferror(1.2*I18+1.1*H18+1.05*G18+1*F18, "") -> 20.06 | E18: =iferror(vlookup($A18, 'Player Game Stats'!$K:$T, 4, False), "") -> 19.2 | F18: =iferror(vlookup($A18, 'Player Game Stats'!$K:$T, 5, False), "") -> 11 | G18: =iferror(vlookup($A18, 'Player Game Stats'!$K:$T, 6, False), "") -> 0.8 | H18: =iferror(vlookup($A18, 'Player Game Stats'!$K:$T, 7, False), "") -> 6.6 | I18: =iferror(vlookup($A18, 'Player Game Stats'!$K:$T, 8, False), "") -> 0.8 | J18: =iferror(vlookup($A18, 'Player Game Stats'!$K:$T, 9, False), "") -> 23 | K18: =iferror(vlookup($A18, 'Player Game Stats'!$K:$T, 10, False), "") -> 0.4549763 | L18: =K18*D18 -> 9.1268246 | M18: =iferror(L18*$L$75, "") -> 24.606945
A19: =Draft!C50 -> Kevin Zhou | B19: =iferror(vlookup($A19, 'Player Game Stats'!$K:$T, 2, False), "") -> 4 | C19: =iferror(vlookup($A19, 'Player Game Stats'!$K:$T, 3, False), "") -> 0.5 | D19: =iferror(1.2*I19+1.1*H19+1.05*G19+1*F19, "") -> 19.875 | E19: =iferror(vlookup($A19, 'Player Game Stats'!$K:$T, 4, False), "") -> 16.75 | F19: =iferror(vlookup($A19, 'Player Game Stats'!$K:$T, 5, False), "") -> 7.75 | G19: =iferror(vlookup($A19, 'Player Game Stats'!$K:$T, 6, False), "") -> 0.5 | H19: =iferror(vlookup($A19, 'Player Game Stats'!$K:$T, 7, False), "") -> 10 | I19: =iferror(vlookup($A19, 'Player Game Stats'!$K:$T, 8, False), "") -> 0.5 | J19: =iferror(vlookup($A19, 'Player Game Stats'!$K:$T, 9, False), "") -> 23 | K19: =iferror(vlookup($A19, 'Player Game Stats'!$K:$T, 10, False), "") -> 0.42138365 | L19: =K19*D19 -> 8.375 | M19: =iferror(L19*$L$75, "") -> 22.579941
A20: =Draft!C51 -> Somil | B20: =iferror(vlookup($A20, 'Player Game Stats'!$K:$T, 2, False), "") -> 3 | C20: =iferror(vlookup($A20, 'Player Game Stats'!$K:$T, 3, False), "") -> 0.66666667 | D20: =iferror(1.2*I20+1.1*H20+1.05*G20+1*F20, "") -> 14.333333 | E20: =iferror(vlookup($A20, 'Player Game Stats'!$K:$T, 4, False), "") -> 13.666667 | F20: =iferror(vlookup($A20, 'Player Game Stats'!$K:$T, 5, False), "") -> 7 | G20: =iferror(vlookup($A20, 'Player Game Stats'!$K:$T, 6, False), "") -> 0.66666667 | H20: =iferror(vlookup($A20, 'Player Game Stats'!$K:$T, 7, False), "") -> 5.6666667 | I20: =iferror(vlookup($A20, 'Player Game Stats'!$K:$T, 8, False), "") -> 0.33333333 | J20: =iferror(vlookup($A20, 'Player Game Stats'!$K:$T, 9, False), "") -> 25 | K20: =iferror(vlookup($A20, 'Player Game Stats'!$K:$T, 10, False), "") -> 0.35344828 | L20: =K20*D20 -> 5.066092 | M20: =iferror(L20*$L$75, "") -> 13.658753
A21: =Draft!C52 -> Suyoag | B21: =iferror(vlookup($A21, 'Player Game Stats'!$K:$T, 2, False), "") -> 2 | C21: =iferror(vlookup($A21, 'Player Game Stats'!$K:$T, 3, False), "") -> 0 | D21: =iferror(1.2*I21+1.1*H21+1.05*G21+1*F21, "") -> 14.95 | E21: =iferror(vlookup($A21, 'Player Game Stats'!$K:$T, 4, False), "") -> 14.5 | F21: =iferror(vlookup($A21, 'Player Game Stats'!$K:$T, 5, False), "") -> 10 | G21: =iferror(vlookup($A21, 'Player Game Stats'!$K:$T, 6, False), "") -> 0 | H21: =iferror(vlookup($A21, 'Player Game Stats'!$K:$T, 7, False), "") -> 4.5 | I21: =iferror(vlookup($A21, 'Player Game Stats'!$K:$T, 8, False), "") -> 0 | J21: =iferror(vlookup($A21, 'Player Game Stats'!$K:$T, 9, False), "") -> 24.5 | K21: =iferror(vlookup($A21, 'Player Game Stats'!$K:$T, 10, False), "") -> 0.37179487 | L21: =K21*D21 -> 5.5583333 | M21: =iferror(L21*$L$75, "") -> 14.985891
A22: =Draft!C53 -> Will Ho | B22: =iferror(vlookup($A22, 'Player Game Stats'!$K:$T, 2, False), "") -> 4 | C22: =iferror(vlookup($A22, 'Player Game Stats'!$K:$T, 3, False), "") -> 0.5 | D22: =iferror(1.2*I22+1.1*H22+1.05*G22+1*F22, "") -> 12.2875 | E22: =iferror(vlookup($A22, 'Player Game Stats'!$K:$T, 4, False), "") -> 11.75 | F22: =iferror(vlookup($A22, 'Player Game Stats'!$K:$T, 5, False), "") -> 6.75 | G22: =iferror(vlookup($A22, 'Player Game Stats'!$K:$T, 6, False), "") -> 0.75 | H22: =iferror(vlookup($A22, 'Player Game Stats'!$K:$T, 7, False), "") -> 3.5 | I22: =iferror(vlookup($A22, 'Player Game Stats'!$K:$T, 8, False), "") -> 0.75 | J22: =iferror(vlookup($A22, 'Player Game Stats'!$K:$T, 9, False), "") -> 25.5 | K22: =iferror(vlookup($A22, 'Player Game Stats'!$K:$T, 10, False), "") -> 0.31543624 | L22: =K22*D22 -> 3.8759228 | M22: =iferror(L22*$L$75, "") -> 10.449923
A23: =Draft!C54 -> Nagle | B23: =iferror(vlookup($A23, 'Player Game Stats'!$K:$T, 2, False), "") -> 1 | C23: =iferror(vlookup($A23, 'Player Game Stats'!$K:$T, 3, False), "") -> 1 | D23: =iferror(1.2*I23+1.1*H23+1.05*G23+1*F23, "") -> 10.6 | E23: =iferror(vlookup($A23, 'Player Game Stats'!$K:$T, 4, False), "") -> 10 | F23: =iferror(vlookup($A23, 'Player Game Stats'!$K:$T, 5, False), "") -> 4 | G23: =iferror(vlookup($A23, 'Player Game Stats'!$K:$T, 6, False), "") -> 0 | H23: =iferror(vlookup($A23, 'Player Game Stats'!$K:$T, 7, False), "") -> 6 | I23: =iferror(vlookup($A23, 'Player Game Stats'!$K:$T, 8, False), "") -> 0 | J23: =iferror(vlookup($A23, 'Player Game Stats'!$K:$T, 9, False), "") -> 27 | K23: =iferror(vlookup($A23, 'Player Game Stats'!$K:$T, 10, False), "") -> 0.27027027 | L23: =K23*D23 -> 2.8648649 | M23: =iferror(L23*$L$75, "") -> 7.7239975
A24: =Draft!C55 | B24: =iferror(vlookup($A24, 'Player Game Stats'!$K:$T, 2, False), "") | C24: =iferror(vlookup($A24, 'Player Game Stats'!$K:$T, 3, False), "") | D24: =iferror(1.2*I24+1.1*H24+1.05*G24+1*F24, "") -> 0 | E24: =iferror(vlookup($A24, 'Player Game Stats'!$K:$T, 4, False), "") | F24: =iferror(vlookup($A24, 'Player Game Stats'!$K:$T, 5, False), "") | G24: =iferror(vlookup($A24, 'Player Game Stats'!$K:$T, 6, False), "") | H24: =iferror(vlookup($A24, 'Player Game Stats'!$K:$T, 7, False), "") | I24: =iferror(vlookup($A24, 'Player Game Stats'!$K:$T, 8, False), "") | J24: =iferror(vlookup($A24, 'Player Game Stats'!$K:$T, 9, False), "") | K24: =iferror(vlookup($A24, 'Player Game Stats'!$K:$T, 10, False), "") | L24: =K24*D24 -> 0 | M24: =iferror(L24*$L$75, "") -> 0
A25: =Draft!C56 | B25: =iferror(vlookup($A25, 'Player Game Stats'!$K:$T, 2, False), "") | C25: =iferror(vlookup($A25, 'Player Game Stats'!$K:$T, 3, False), "") | D25: =iferror(1.2*I25+1.1*H25+1.05*G25+1*F25, "") -> 0 | E25: =iferror(vlookup($A25, 'Player Game Stats'!$K:$T, 4, False), "") | F25: =iferror(vlookup($A25, 'Player Game Stats'!$K:$T, 5, False), "") | G25: =iferror(vlookup($A25, 'Player Game Stats'!$K:$T, 6, False), "") | H25: =iferror(vlookup($A25, 'Player Game Stats'!$K:$T, 7, False), "") | I25: =iferror(vlookup($A25, 'Player Game Stats'!$K:$T, 8, False), "") | J25: =iferror(vlookup($A25, 'Player Game Stats'!$K:$T, 9, False), "") | K25: =iferror(vlookup($A25, 'Player Game Stats'!$K:$T, 10, False), "") | L25: =K25*D25 -> 0 | M25: =iferror(L25*$L$75, "") -> 0
A26: =Draft!D44 -> Taran | B26: =iferror(vlookup($A26, 'Player Game Stats'!$U:$AD, 2, False), "") -> 7 | C26: =iferror(vlookup($A26, 'Player Game Stats'!$U:$AD, 3, False), "") -> 0.28571429 | D26: =iferror(1.2*I26+1.1*H26+1.05*G26+1*F26, "") -> 20.178571 | E26: =iferror(vlookup($A26, 'Player Game Stats'!$U:$AD, 4, False), "") -> 18.857143 | F26: =iferror(vlookup($A26, 'Player Game Stats'!$U:$AD, 5, False), "") -> 6.5714286 | G26: =iferror(vlookup($A26, 'Player Game Stats'!$U:$AD, 6, False), "") -> 3 | H26: =iferror(vlookup($A26, 'Player Game Stats'!$U:$AD, 7, False), "") -> 6.8571429 | I26: =iferror(vlookup($A26, 'Player Game Stats'!$U:$AD, 8, False), "") -> 2.4285714 | J26: =iferror(vlookup($A26, 'Player Game Stats'!$U:$AD, 9, False), "") -> 26.714286 | K26: =iferror(vlookup($A26, 'Player Game Stats'!$U:$AD, 10, False), "") -> 0.4137931 | L26: =K26*D26 -> 8.3497537 | M26: =iferror(L26*$L$75, "") -> 22.511874
A27: =Draft!D46 -> Guel | B27: =iferror(vlookup($A27, 'Player Game Stats'!$U:$AD, 2, False), "") -> 0 | C27: =iferror(vlookup($A27, 'Player Game Stats'!$U:$AD, 3, False), "") | D27: =iferror(1.2*I27+1.1*H27+1.05*G27+1*F27, "") -> 0 | E27: =iferror(vlookup($A27, 'Player Game Stats'!$U:$AD, 4, False), "") | F27: =iferror(vlookup($A27, 'Player Game Stats'!$U:$AD, 5, False), "") | G27: =iferror(vlookup($A27, 'Player Game Stats'!$U:$AD, 6, False), "") | H27: =iferror(vlookup($A27, 'Player Game Stats'!$U:$AD, 7, False), "") | I27: =iferror(vlookup($A27, 'Player Game Stats'!$U:$AD, 8, False), "") | J27: =iferror(vlookup($A27, 'Player Game Stats'!$U:$AD, 9, False), "") | K27: =iferror(vlookup($A27, 'Player Game Stats'!$U:$AD, 10, False), "") | L27: =K27*D27 -> 0 | M27: =iferror(L27*$L$75, "") -> 0
A28: =Draft!D47 -> Mike Harrison | B28: =iferror(vlookup($A28, 'Player Game Stats'!$U:$AD, 2, False), "") -> 0 | C28: =iferror(vlookup($A28, 'Player Game Stats'!$U:$AD, 3, False), "") | D28: =iferror(1.2*I28+1.1*H28+1.05*G28+1*F28, "") -> 0 | E28: =iferror(vlookup($A28, 'Player Game Stats'!$U:$AD, 4, False), "") | F28: =iferror(vlookup($A28, 'Player Game Stats'!$U:$AD, 5, False), "") | G28: =iferror(vlookup($A28, 'Player Game Stats'!$U:$AD, 6, False), "") | H28: =iferror(vlookup($A28, 'Player Game Stats'!$U:$AD, 7, False), "") | I28: =iferror(vlookup($A28, 'Player Game Stats'!$U:$AD, 8, False), "") | J28: =iferror(vlookup($A28, 'Player Game Stats'!$U:$AD, 9, False), "") | K28: =iferror(vlookup($A28, 'Player Game Stats'!$U:$AD, 10, False), "") | L28: =K28*D28 -> 0 | M28: =iferror(L28*$L$75, "") -> 0
A29: =Draft!D48 -> Madams | B29: =iferror(vlookup($A29, 'Player Game Stats'!$U:$AD, 2, False), "") -> 7 | C29: =iferror(vlookup($A29, 'Player Game Stats'!$U:$AD, 3, False), "") -> 0.28571429 | D29: =iferror(1.2*I29+1.1*H29+1.05*G29+1*F29, "") -> 16.021429 | E29: =iferror(vlookup($A29, 'Player Game Stats'!$U:$AD, 4, False), "") -> 15.285714 | F29: =iferror(vlookup($A29, 'Player Game Stats'!$U:$AD, 5, False), "") -> 8.2857143 | G29: =iferror(vlookup($A29, 'Player Game Stats'!$U:$AD, 6, False), "") -> 1 | H29: =iferror(vlookup($A29, 'Player Game Stats'!$U:$AD, 7, False), "") -> 5.1428571 | I29: =iferror(vlookup($A29, 'Player Game Stats'!$U:$AD, 8, False), "") -> 0.85714286 | J29: =iferror(vlookup($A29, 'Player Game Stats'!$U:$AD, 9, False), "") -> 28.428571 | K29: =iferror(vlookup($A29, 'Player Game Stats'!$U:$AD, 10, False), "") -> 0.3496732 | L29: =K29*D29 -> 5.6022642 | M29: =iferror(L29*$L$75, "") -> 15.104334
