Workbook

Sheet General Info
A1: Example Schedule | B1: Date | D1: Bylaws
A2: Draft | B2: 45896 | E2: Members
A3: Game 1 | B3: August 30th/31st | F3: =Draft!B24 -> Gargantuan | G3: =Draft!C24 -> Team C | H3: =Draft!D24 -> Candice? | I3: =Draft!E24 -> Team E | J3: =Draft!F24 -> Migos | K3: =Draft!G24 -> Team F
A4: Game 2 | B4: September 6th/7th | E4: Captain | F4: =Draft!B25 -> Tyler | G4: =Draft!C25 -> Du | H4: =Draft!D25 -> John | I4: =Draft!E25 -> Guel | J4: =Draft!F25 -> Arnav | K4: =Draft!G25 -> Jay
A5: Combine | E5: Keeper | F5: =Draft!B26 -> Lucas | G5: =Draft!C26 -> Neo | H5: =Draft!D26 -> Cole | I5: =Draft!E26 -> Pasha | J5: =Draft!F26 -> Brendan | K5: =Draft!G26 -> Schmid
A6: Game 3 | B6: September 13th/14th | E6: Pick 1 | F6: =Draft!B27 -> Porco | G6: =Draft!C27 -> Fritz | H6: =Draft!D27 -> Dannegger | I6: =Draft!E27 -> Yost | J6: =Draft!F27 -> Kumbatovic | K6: =Draft!G27 -> DC
A7: Pledge Draft | E7: Pick 2 | F7: =Draft!B28 -> Andy Yu | G7: =Draft!C28 -> Eric | H7: =Draft!D28 -> KZ | I7: =Draft!E28 -> Sean | J7: =Draft!F28 -> Paul | K7: =Draft!G28 -> Steven
A8: Game 4 | B8: September 20th/21st | E8: Pick 3 | F8: =Draft!B29 -> Dli | G8: =Draft!C29 -> Ilt | H8: =Draft!D29 -> Adi | I8: =Draft!E29 -> Samos | J8: =Draft!F29 -> Raymond | K8: =Draft!G29 -> Dave
A9: Game 5 | B9: September 27th/28th | E9: Pick 4 | F9: =Draft!B30 -> Somil | G9: =Draft!C30 -> Matvey | H9: =Draft!D30 -> Gavin | I9: =Draft!E30 -> Soho | J9: =Draft!F30 -> TC | K9: =Draft!G30 -> Lulu
A10: Game 6 | B10: October 4th/5th | E10: Pick 5 | F10: =Draft!B31 -> VIshal | G10: =Draft!C31 -> James | H10: =Draft!D31 -> David | I10: =Draft!E31 -> Haldar | J10: =Draft!F31 -> Kyi | K10: =Draft!G31 -> Will
A11: Bye Week | B11: October 11th | E11: Pick 6 | F11: Sam | G11: Sebastian | H11: Kento | I11: =Draft!E32 -> Dji | J11: =Draft!F32 -> Jwu | K11: =Draft!G32 -> Hershey
A12: Bye Week | B12: October 18th | E12: Pick 7 | F12: Charlie | G12: Erik | H12: Jacob | I12: Lubke | J12: Parker | K12: Byun
A13: Game 7 | B13: October 25th/26th | E13: Pick 8 | F13: Daniel | G13: Jack | H13: =Draft!D34 | I13: David (pledge) | J13: Henry | K13: Ted
A14: Semifinals (1) | B14: November 1st/2nd | E14: Pick 9 | F14: =Draft!B35 | G14: =Draft!C35 | H14: =Draft!D35 | I14: Will | J14: Ayush | K14: Gio
A15: Semifinals (2/3) | B15: November 8th/9th | E15: Pledge 1 | F15: =Draft!B36 | G15: =Draft!C36 | H15: =Draft!D36 | I15: =Draft!E36 | J15: =Draft!F36 | K15: =Draft!G36
A16: Finals | B16: November 15th/16th | E16: Pledge 2
E17: Pledge 3
E18: Pledge 4

Sheet Draft
A1: Draft Sheet | B1: Bank
A12: Captain | B12: Tyler | C12: Du | D12: John | E12: Guel | F12: Arnav | G12: Jay | I12: Current Trades
A13: Keeper | B13: Lucas | C13: Neo | D13: Cole | E13: Pasha | F13: Brendan | G13: Schmid
A14: 1st Round | B14: Porco | C14: Fritz | D14: Dannegger | E14: Yost | F14: Kumbatovic | G14: DC
A15: 2nd Round | B15: Andy Yu | C15: Dli | D15: KZ | E15: Sean | F15: Paul | G15: Steven
A16: 3rd Round | B16: Somil | C16: Eric | D16: Vishal | E16: Samos | F16: Raymond | G16: Dave
A17: 4th Round | B17: ilt | C17: Matvey | D17: Adi | E17: Soho | F17: TC | G17: Lulu
A18: 5th Round | B18: Gavin | C18: James | D18: David | E18: Haldar | F18: Kyi | G18: Will | I18: Future Trades:
A19: 6th Round | E19: Dji | F19: Jwu | G19: Hershey
A20: 7th Round
A21: 8th Round
A23: Teams
B24: Gargantuan | C24: Team C | D24: Candice? | E24: Team E | F24: Migos | G24: Team F
A25: Captain | B25: Tyler | C25: Du | D25: John | E25: Guel | F25: Arnav | G25: Jay
A26: Keeper | B26: Lucas | C26: Neo | D26: Cole | E26: Pasha | F26: Brendan | G26: Schmid
A27: Pick 1 | B27: Porco | C27: Fritz | D27: Dannegger | E27: Yost | F27: Kumbatovic | G27: DC
A28: Pick 2 | B28: Andy Yu | C28: Eric | D28: KZ | E28: Sean | F28: Paul | G28: Steven
A29: Pick 3 | B29: Dli | C29: Ilt | D29: Adi | E29: Samos | F29: Raymond | G29: Dave
A30: Pick 4 | B30: Somil | C30: Matvey | D30: Gavin | E30: Soho | F30: TC | G30: Lulu
A31: Pick 5 | B31: VIshal | C31: James | D31: David | E31: Haldar | F31: Kyi | G31: Will
A32: Pick 6 | B32: Sam | C32: Sebastian | D32: Kento | E32: Dji | F32: Jwu | G32: Hershey
A33: Pick 7 | B33: Charlie | C33: Erik | D33: Jacob | E33: Lubke | F33: Parker | G33: Byun
A34: Pick 8 | B34: Daniel | C34: Jack | E34: David (pledge) | F34: Henry | G34: Ted
A35: Pick 9 | E35: Will | F35: Ayush | G35: Gio
A37: Pledge Draft | B37: Bank
A44: Teams
B45: =B24 -> Gargantuan | C45: =C24 -> Team C | D45: =D24 -> Candice? | E45: =E24 -> Team E | F45: =F24 -> Migos | G45: =G24 -> Team F
A46: Captain | B46: Tyler | C46: Du | D46: John | E46: Guel | F46: Arnav | G46: Jay
A48: 1 | B48: Lucas | C48: Neo | D48: Cole | E48: Pasha | F48: Blark | G48: Schmid
A49: =A48+1 -> 2 | B49: Porco | C49: Fritz | D49: Dannegger | E49: Yost | F49: Kumba | G49: DC
A50: =A49+1 -> 3 | B50: Andy Yu | C50: Eric | D50: KZ | E50: Sean | F50: Paul | G50: Steven
A51: =A50+1 -> 4 | B51: Dli | C51: Ilt | D51: Adi | E51: Samos | F51: Raymond | G51: Dave
A52: =A51+1 -> 5 | B52: Somil | C52: Matvey | D52: Gavin | E52: Soho | F52: TC | G52: Lulu
A53: =A52+1 -> 6 | B53: Vishal | C53: James | D53: DPJ | E53: Haldar | F53: Kyi | G53: Will Blankenship
A54: =A53+1 -> 7 | B54: Sam Ram | C54: Sebastian F | D54: Kento | E54: Dji | F54: Jwu | G54: Hershey
A55: =A54+1 -> 8 | B55: Chubbs | C55: Erik | D55: Jacob | E55: Luebke | F55: Parker
A56: =A55+1 -> 9 | B56: Daniel Mas | C56: Jack Flori | E56: David Cerrato | F56: Henry | G56: Ted
A57: =A56+1 -> 10 | E57: Will He | F57: Ayush | G57: Gio
A58: =A57+1 -> 11

Sheet Team Stats
A1: =Draft!B25 -> Tyler | G1: =Draft!D25 -> John | M1: **edit this column
A2: =Draft!B24 -> Gargantuan | B2: Opponent | C2: Home/Away | D2: Result | E2: Margin | G2: =Draft!D24 -> Candice? | H2: Opponent | I2: Home/Away | J2: Result | K2: Margin
A3: Game 1 | B3: =VLOOKUP(A2, 'Full Schedule'!$A$3:$B$9, 2, False) -> Team E | C3: =if(match(A2, 'Full Schedule'!$A$3:$A$8, 0)<4, "Home", "Away") -> Away | D3: =if('Week 1'!$A$1=A2, 'Week 1'!$F$1, if('Week 1'!$K$1=A2, 'Week 1'!$P$1, if('Week 1'!$A$21=A2, 'Week 1'!$F$21, if('Week 1'!$K$21=A2, 'Week 1'!$P$21, if('Week 1'!$A$41=A2, 'Week 1'!$F$41, if('Week 1'!$K$41=A2, 'Week 1'!$P$41)))))) -> Loss | E3: =if('Week 1'!$A$1=A2, 'Week 1'!$I$1, if('Week 1'!$K$1=A2, 'Week 1'!$S$1, if('Week 1'!$A$21=A2, 'Week 1'!$I$21, if('Week 1'!$K$21=A2, 'Week 1'!$S$21, if('Week 1'!$A$41=A2, 'Week 1'!$I$41, if('Week 1'!$K$41=A2, 'Week 1'!$S$41)))))) -> -1 | G3: Game 1 | H3: =VLOOKUP(G2, 'Full Schedule'!$A$3:$B$9, 2, False) -> Migos | I3: =if(match(G2, 'Full Schedule'!$A$3:$A$8, 0)<4, "Home", "Away") -> Home | J3: =if('Week 1'!$A$1=G2, 'Week 1'!$F$1, if('Week 1'!$K$1=G2, 'Week 1'!$P$1, if('Week 1'!$A$21=G2, 'Week 1'!$F$21, if('Week 1'!$K$21=G2, 'Week 1'!$P$21, if('Week 1'!$A$41=G2, 'Week 1'!$F$41, if('Week 1'!$K$41=G2, 'Week 1'!$P$41)))))) -> Win | K3: =if('Week 1'!$A$1=G2, 'Week 1'!$I$1, if('Week 1'!$K$1=G2, 'Week 1'!$S$1, if('Week 1'!$A$21=G2, 'Week 1'!$I$21, if('Week 1'!$K$21=G2, 'Week 1'!$S$21, if('Week 1'!$A$41=G2, 'Week 1'!$I$41, if('Week 1'!$K$41=G2, 'Week 1'!$S$41)))))) -> 11
A4: Game 2 | B4: =vlookup(A2, 'Full Schedule'!$C$3:$D$8, 2, False) -> Candice? | C4: =if(match(A2, 'Full Schedule'!$C$3:$C$8, 0)<4, "Home", "Away") -> Home | D4: =if('Week 2'!$A$1=A2, 'Week 2'!$F$1, if('Week 2'!$K$1=A2, 'Week 2'!$P$1, if('Week 2'!$A$21=A2, 'Week 2'!$F$21, if('Week 2'!$K$21=A2, 'Week 2'!$P$21, if('Week 2'!$A$41=A2, 'Week 2'!$F$41, if('Week 2'!$K$41=A2, 'Week 2'!$P$41)))))) -> Loss | E4: =if('Week 2'!$A$1=A2, 'Week 2'!$I$1, if('Week 2'!$K$1=A2, 'Week 2'!$S$1, if('Week 2'!$A$21=A2, 'Week 2'!$I$21, if('Week 2'!$K$21=A2, 'Week 2'!$S$21, if('Week 2'!$A$41=A2, 'Week 2'!$I$41, if('Week 2'!$K$41=A2, 'Week 2'!$S$41)))))) -> -19 | G4: Game 2 | H4: =vlookup(G2, 'Full Schedule'!$C$3:$D$8, 2, False) -> Gargantuan | I4: =if(match(G2, 'Full Schedule'!$C$3:$C$8, 0)<4, "Home", "Away") -> Away | J4: =if('Week 2'!$A$1=G2, 'Week 2'!$F$1, if('Week 2'!$K$1=G2, 'Week 2'!$P$1, if('Week 2'!$A$21=G2, 'Week 2'!$F$21, if('Week 2'!$K$21=G2, 'Week 2'!$P$21, if('Week 2'!$A$41=G2, 'Week 2'!$F$41, if('Week 2'!$K$41=G2, 'Week 2'!$P$41)))))) -> Win | K4: =if('Week 2'!$A$1=G2, 'Week 2'!$I$1, if('Week 2'!$K$1=G2, 'Week 2'!$S$1, if('Week 2'!$A$21=G2, 'Week 2'!$I$21, if('Week 2'!$K$21=G2, 'Week 2'!$S$21, if('Week 2'!$A$41=G2, 'Week 2'!$I$41, if('Week 2'!$K$41=G2, 'Week 2'!$S$41)))))) -> 19
A5: Game 3 | B5: =vlookup(A2, 'Full Schedule'!$E$3:$F$8, 2, False) -> Migos | C5: =if(match(A2, 'Full Schedule'!$E$3:$E$8, 0)<4, "Home", "Away") -> Away | D5: =if('Week 3'!$A$1=A2, 'Week 3'!$F$1, if('Week 3'!$K$1=A2, 'Week 3'!$P$1, if('Week 3'!$A$21=A2, 'Week 3'!$F$21, if('Week 3'!$K$21=A2, 'Week 3'!$P$21, if('Week 3'!$A$41=A2, 'Week 3'!$F$41, if('Week 3'!$K$41=A2, 'Week 3'!$P$41)))))) -> Loss | E5: =if('Week 3'!$A$1=A2, 'Week 3'!$I$1, if('Week 3'!$K$1=A2, 'Week 3'!$S$1, if('Week 3'!$A$21=A2, 'Week 3'!$I$21, if('Week 3'!$K$21=A2, 'Week 3'!$S$21, if('Week 3'!$A$41=A2, 'Week 3'!$I$41, if('Week 3'!$K$41=A2, 'Week 3'!$S$41)))))) -> -6 | G5: Game 3 | H5: =vlookup(G2, 'Full Schedule'!$E$3:$F$8, 2, False) -> Team F | I5: =if(match(G2, 'Full Schedule'!$E$3:$E$8, 0)<4, "Home", "Away") -> Away | J5: =if('Week 3'!$A$1=G2, 'Week 3'!$F$1, if('Week 3'!$K$1=G2, 'Week 3'!$P$1, if('Week 3'!$A$21=G2, 'Week 3'!$F$21, if('Week 3'!$K$21=G2, 'Week 3'!$P$21, if('Week 3'!$A$41=G2, 'Week 3'!$F$41, if('Week 3'!$K$41=G2, 'Week 3'!$P$41)))))) -> Win | K5: =if('Week 3'!$A$1=G2, 'Week 3'!$I$1, if('Week 3'!$K$1=G2, 'Week 3'!$S$1, if('Week 3'!$A$21=G2, 'Week 3'!$I$21, if('Week 3'!$K$21=G2, 'Week 3'!$S$21, if('Week 3'!$A$41=G2, 'Week 3'!$I$41, if('Week 3'!$K$41=G2, 'Week 3'!$S$41)))))) -> 21 | M5: West
A6: Game 4 | B6: =vlookup(A2, 'Full Schedule'!$G$3:$H$8, 2, False) -> Candice? | C6: =if(match(A2, 'Full Schedule'!$G$3:$G$8, 0)<4, "Home", "Away") -> Away | D6: =if('Week 4'!$A$1=A2, 'Week 4'!$F$1, if('Week 4'!$K$1=A2, 'Week 4'!$P$1, if('Week 4'!$A$21=A2, 'Week 4'!$F$21, if('Week 4'!$K$21=A2, 'Week 4'!$P$21, if('Week 4'!$A$41=A2, 'Week 4'!$F$41, if('Week 4'!$K$41=A2, 'Week 4'!$P$41)))))) -> Win | E6: =if('Week 4'!$A$1=A2, 'Week 4'!$I$1, if('Week 4'!$K$1=A2, 'Week 4'!$S$1, if('Week 4'!$A$21=A2, 'Week 4'!$I$21, if('Week 4'!$K$21=A2, 'Week 4'!$S$21, if('Week 4'!$A$41=A2, 'Week 4'!$I$41, if('Week 4'!$K$41=A2, 'Week 4'!$S$41)))))) -> 3 | G6: Game 4 | H6: =vlookup(G2, 'Full Schedule'!$G$3:$H$8, 2, False) -> Gargantuan | I6: =if(match(G2, 'Full Schedule'!$G$3:$G$8, 0)<4, "Home", "Away") -> Home | J6: =if('Week 4'!$A$1=G2, 'Week 4'!$F$1, if('Week 4'!$K$1=G2, 'Week 4'!$P$1, if('Week 4'!$A$21=G2, 'Week 4'!$F$21, if('Week 4'!$K$21=G2, 'Week 4'!$P$21, if('Week 4'!$A$41=G2, 'Week 4'!$F$41, if('Week 4'!$K$41=G2, 'Week 4'!$P$41)))))) -> Loss | K6: =if('Week 4'!$A$1=G2, 'Week 4'!$I$1, if('Week 4'!$K$1=G2, 'Week 4'!$S$1, if('Week 4'!$A$21=G2, 'Week 4'!$I$21, if('Week 4'!$K$21=G2, 'Week 4'!$S$21, if('Week 4'!$A$41=G2, 'Week 4'!$I$41, if('Week 4'!$K$41=G2, 'Week 4'!$S$41)))))) -> -3 | N6: Record | O6: Win % | P6: Margin
A7: Game 5 | B7: =vlookup(A2, 'Full Schedule'!$I$3:$J$8, 2, False) -> Migos | C7: =if(match(A2, 'Full Schedule'!$I$3:$I$8, 0)<4, "Home", "Away") -> Home | D7: =if('Week 5'!$A$1=A2, 'Week 5'!$F$1, if('Week 5'!$K$1=A2, 'Week 5'!$P$1, if('Week 5'!$A$21=A2, 'Week 5'!$F$21, if('Week 5'!$K$21=A2, 'Week 5'!$P$21, if('Week 5'!$A$41=A2, 'Week 5'!$F$41, if('Week 5'!$K$41=A2, 'Week 5'!$P$41)))))) -> Loss | E7: =if('Week 5'!$A$1=A2, 'Week 5'!$I$1, if('Week 5'!$K$1=A2, 'Week 5'!$S$1, if('Week 5'!$A$21=A2, 'Week 5'!$I$21, if('Week 5'!$K$21=A2, 'Week 5'!$S$21, if('Week 5'!$A$41=A2, 'Week 5'!$I$41, if('Week 5'!$K$41=A2, 'Week 5'!$S$41)))))) -> -5 | G7: Game 5 | H7: =vlookup(G2, 'Full Schedule'!$I$3:$J$8, 2, False) -> Team E | I7: =if(match(G2, 'Full Schedule'!$I$3:$I$8, 0)<4, "Home", "Away") -> Home | J7: =if('Week 5'!$A$1=G2, 'Week 5'!$F$1, if('Week 5'!$K$1=G2, 'Week 5'!$P$1, if('Week 5'!$A$21=G2, 'Week 5'!$F$21, if('Week 5'!$K$21=G2, 'Week 5'!$P$21, if('Week 5'!$A$41=G2, 'Week 5'!$F$41, if('Week 5'!$K$41=G2, 'Week 5'!$P$41)))))) -> Loss | K7: =if('Week 5'!$A$1=G2, 'Week 5'!$I$1, if('Week 5'!$K$1=G2, 'Week 5'!$S$1, if('Week 5'!$A$21=G2, 'Week 5'!$I$21, if('Week 5'!$K$21=G2, 'Week 5'!$S$21, if('Week 5'!$A$41=G2, 'Week 5'!$I$41, if('Week 5'!$K$41=G2, 'Week 5'!$S$41)))))) -> -1 | M7: =A15 -> Team C | N7: 45691 | O7: =if($M7=$A$2, D$12, if($M7=$G$2, J$12, if($M7=$A$15, D$25, if($M7=$G$15, J$25, if($M7=$A$28, D$38, if($M7=$G$28, J$38)))))) -> 0.42857143 | P7: =if($M7=$A$2, E$12, if($M7=$G$2, K$12, if($M7=$A$15, E$25, if($M7=$G$15, K$25, if($M7=$A$28, E$38, if($M7=$G$28, K$38)))))) -> -40
A8: Game 6 | B8: =vlookup(A2, 'Full Schedule'!$K$3:$L$8, 2, False) -> Team C | C8: =if(match(A2, 'Full Schedule'!$K$3:$K$8, 0)<4, "Home", "Away") -> Home | D8: =if('Week 6'!$A$1=A2, 'Week 6'!$F$1, if('Week 6'!$K$1=A2, 'Week 6'!$P$1, if('Week 6'!$A$21=A2, 'Week 6'!$F$21, if('Week 6'!$K$21=A2, 'Week 6'!$P$21, if('Week 6'!$A$41=A2, 'Week 6'!$F$41, if('Week 6'!K$41=A2, 'Week 6'!$P$41)))))) -> Win | E8: =if('Week 6'!$A$1=A2, 'Week 6'!$I$1, if('Week 6'!$K$1=A2, 'Week 6'!$S$1, if('Week 6'!$A$21=A2, 'Week 6'!$I$21, if('Week 6'!$K$21=A2, 'Week 6'!$S$21, if('Week 6'!$A$41=A2, 'Week 6'!$I$41, if('Week 6'!$K$41=A2, 'Week 6'!$S$41)))))) -> 6 | G8: Game 6 | H8: =vlookup(G2, 'Full Schedule'!$K$3:$L$8, 2, False) -> Migos | I8: =if(match(G2, 'Full Schedule'!$K$3:$K$8, 0)<4, "Home", "Away") -> Away | J8: =if('Week 6'!$A$1=G2, 'Week 6'!$F$1, if('Week 6'!$K$1=G2, 'Week 6'!$P$1, if('Week 6'!$A$21=G2, 'Week 6'!$F$21, if('Week 6'!$K$21=G2, 'Week 6'!$P$21, if('Week 6'!$A$41=G2, 'Week 6'!$F$41, if('Week 6'!$K$41=G2, 'Week 6'!$P$41)))))) -> Loss | K8: =if('Week 6'!$A$1=G2, 'Week 6'!$I$1, if('Week 6'!$K$1=G2, 'Week 6'!$S$1, if('Week 6'!$A$21=G2, 'Week 6'!$I$21, if('Week 6'!$K$21=G2, 'Week 6'!$S$21, if('Week 6'!$A$41=G2, 'Week 6'!$I$41, if('Week 6'!$K$41=G2, 'Week 6'!$S$41)))))) -> -1 | M8: =Draft!E24 -> Team E | N8: 45719 | O8: =if($M8=$A$2, D$12, if($M8=$G$2, J$12, if($M8=$A$15, D$25, if($M8=$G$15, J$25, if($M8=$A$28, D$38, if($M8=$G$28, J$38)))))) -> 0.5 | P8: =if($M8=$A$2, E$12, if($M8=$G$2, K$12, if($M8=$A$15, E$25, if($M8=$G$15, K$25, if($M8=$A$28, E$38, if($M8=$G$28, K$38)))))) -> -3
A9: Game 7 | B9: =vlookup(A2, 'Full Schedule'!$M$3:$N$8, 2, False) -> Team F | C9: Split | D9: =if('Week 7'!$A$1=A2, 'Week 7'!$F1, if('Week 7'!$K$1=A2, 'Week 7'!$P$1, if('Week 7'!$A$21=A2, 'Week 7'!$F$21, if('Week 7'!$K$21=A2, 'Week 7'!$P$21, if('Week 7'!$A$41=A2, 'Week 7'!$F$41, if('Week 7'!$K$41=A2, 'Week 7'!$P$41)))))) -> Win | E9: =if('Week 7'!$A$1=A2, 'Week 7'!$I$1, if('Week 7'!$K$1=A2, 'Week 7'!$S$1, if('Week 7'!$A$21=A2, 'Week 7'!$I$21, if('Week 7'!$K$21=A2, 'Week 7'!$S$21, if('Week 7'!$A$41=A2, 'Week 7'!$I$41, if('Week 7'!$K$41=A2, 'Week 7'!$S$41)))))) -> 1 | G9: Game 7 | H9: =vlookup(G2, 'Full Schedule'!$M$3:$N$8, 2, False) -> Team C | I9: Split | J9: =if('Week 7'!$A$1=G2, 'Week 7'!$F1, if('Week 7'!$K$1=G2, 'Week 7'!$P$1, if('Week 7'!$A$21=G2, 'Week 7'!$F$21, if('Week 7'!$K$21=G2, 'Week 7'!$P$21, if('Week 7'!$A$41=G2, 'Week 7'!$F$41, if('Week 7'!$K$41=G2, 'Week 7'!$P$41)))))) -> Loss | K9: =if('Week 7'!$A$1=G2, 'Week 7'!$I$1, if('Week 7'!$K$1=G2, 'Week 7'!$S$1, if('Week 7'!$A$21=G2, 'Week 7'!$I$21, if('Week 7'!$K$21=G2, 'Week 7'!$S$21, if('Week 7'!$A$41=G2, 'Week 7'!$I$41, if('Week 7'!$K$41=G2, 'Week 7'!$S$41)))))) -> -9 | M9: =Draft!G24 -> Team F | N9: =if($M9=$A$2, CONCATENATE(countif($D$3:$D$9, "Win"),"-", countif($D$3:$D$9, "Loss")), if($M9=$G$2, CONCATENATE(countif($J$3:$J$9, "Win"),"-", countif($J$3:$J$9, "Loss")), if($M9=$A$15, CONCATENATE(countif($J$3:$J$9, "Win"),"-", countif($D$16:$D$22, "Loss")), if($M9=$G$15, CONCATENATE(countif($J$16:$J$22, "Win"),"-", countif($J$16:$J$22, "Loss")), if($M9=$A$28, CONCATENATE(countif($D$29:$D$35, "Win"),"-", countif($D$29:$D$35, "Loss")), if($M9=$G$28, CONCATENATE(countif($J$29:$J$35, "Win"),"-", countif($J$29:$J$35, "Loss")))))))) -> 3-4 | O9: =if($M9=$A$2, D$12, if($M9=$G$2, J$12, if($M9=$A$15, D$25, if($M9=$G$15, J$25, if($M9=$A$28, D$38, if($M9=$G$28, J$38)))))) -> 0.42857143 | P9: =if($M9=$A$2, E$12, if($M9=$G$2, K$12, if($M9=$A$15, E$25, if($M9=$G$15, K$25, if($M9=$A$28, E$38, if($M9=$G$28, K$38)))))) -> -4
M11: East
A12: Total | D12: =iferror(countif(D3:D9, "Win")/(countif(D3:D9, "Win")+countif(D3:D9, "Loss")), "") -> 0.42857143 | E12: =SUM(E3:E11) -> -21 | G12: Total | J12: =iferror(countif(J3:J9, "Win")/(countif(J3:J9, "Win")+countif(J3:J9, "Loss")), "") -> 0.42857143 | K12: =SUM(K3:K11) -> 37 | N12: Record | O12: Win % | P12: Margin
M13: =A2 -> Gargantuan | N13: =if($M13=$A$2, CONCATENATE(countif($D$3:$D$9, "Win"),"-", countif($D$3:$D$9, "Loss")), if($M13=$G$2, CONCATENATE(countif($J$3:$J$9, "Win"),"-", countif($J$3:$J$9, "Loss")), if($M13=$A$15, CONCATENATE(countif($J$3:$J$9, "Win"),"-", countif($D$16:$D$22, "Loss")), if($M13=$G$15, CONCATENATE(countif($J$16:$J$22, "Win"),"-", countif($J$16:$J$22, "Loss")), if($M13=$A$28, CONCATENATE(countif($D$29:$D$35, "Win"),"-", countif($D$29:$D$35, "Loss")), if($M13=$G$28, CONCATENATE(countif($J$29:$J$35, "Win"),"-", countif($J$29:$J$35, "Loss")))))))) -> 3-4 | O13: =if($M13=$A$2, D$12, if($M13=$G$2, J$12, if($M13=$A$15, D$25, if($M13=$G$15, J$25, if($M13=$A$28, D$38, if($M13=$G$28, J$38)))))) -> 0.42857143 | P13: =if($M13=$A$2, E$12, if($M13=$G$2, K$12, if($M13=$A$15, E$25, if($M13=$G$15, K$25, if($M13=$A$28, E$38, if($M13=$G$28, K$38)))))) -> -21
A14: =Draft!C25 -> Du | G14: =Draft!E25 -> Guel | M14: =Draft!D24 -> Candice? | N14: =if($M14=$A$2, CONCATENATE(countif($D$3:$D$9, "Win"),"-", countif($D$3:$D$9, "Loss")), if($M14=$G$2, CONCATENATE(countif($J$3:$J$9, "Win"),"-", countif($J$3:$J$9, "Loss")), if($M14=$A$15, CONCATENATE(countif($J$3:$J$9, "Win"),"-", countif($D$16:$D$22, "Loss")), if($M14=$G$15, CONCATENATE(countif($J$16:$J$22, "Win"),"-", countif($J$16:$J$22, "Loss")), if($M14=$A$28, CONCATENATE(countif($D$29:$D$35, "Win"),"-", countif($D$29:$D$35, "Loss")), if($M14=$G$28, CONCATENATE(countif($J$29:$J$35, "Win"),"-", countif($J$29:$J$35, "Loss")))))))) -> 3-4 | O14: =if($M14=$A$2, D$12, if($M14=$G$2, J$12, if($M14=$A$15, D$25, if($M14=$G$15, J$25, if($M14=$A$28, D$38, if($M14=$G$28, J$38)))))) -> 0.42857143 | P14: =if($M14=$A$2, E$12, if($M14=$G$2, K$12, if($M14=$A$15, E$25, if($M14=$G$15, K$25, if($M14=$A$28, E$38, if($M14=$G$28, K$38)))))) -> 37
A15: =Draft!C24 -> Team C | B15: Opponent | C15: Home/Away | D15: Result | E15: Margin | G15: =Draft!E24 -> Team E | H15: Opponent | I15: Home/Away | J15: Result | K15: Margin | M15: =Draft!F24 -> Migos | N15: =if($M15=$A$2, CONCATENATE(countif($D$3:$D$9, "Win"),"-", countif($D$3:$D$9, "Loss")), if($M15=$G$2, CONCATENATE(countif($J$3:$J$9, "Win"),"-", countif($J$3:$J$9, "Loss")), if($M15=$A$15, CONCATENATE(countif($J$3:$J$9, "Win"),"-", countif($D$16:$D$22, "Loss")), if($M15=$G$15, CONCATENATE(countif($J$16:$J$22, "Win"),"-", countif($J$16:$J$22, "Loss")), if($M15=$A$28, CONCATENATE(countif($D$29:$D$35, "Win"),"-", countif($D$29:$D$35, "Loss")), if($M15=$G$28, CONCATENATE(countif($J$29:$J$35, "Win"),"-", countif($J$29:$J$35, "Loss")))))))) -> 6-1 | O15: =if($M15=$A$2, D$12, if($M15=$G$2, J$12, if($M15=$A$15, D$25, if($M15=$G$15, J$25, if($M15=$A$28, D$38, if($M15=$G$28, J$38)))))) -> 0.85714286 | P15: =if($M15=$A$2, E$12, if($M15=$G$2, K$12, if($M15=$A$15, E$25, if($M15=$G$15, K$25, if($M15=$A$28, E$38, if($M15=$G$28, K$38)))))) -> 31
A16: Game 1 | B16: =VLOOKUP(A15, 'Full Schedule'!$A$3:$B$9, 2, False) -> Team F | C16: =if(match(A15, 'Full Schedule'!$A$3:$A$8, 0)<4, "Home", "Away") -> Away | D16: =if('Week 1'!$A$1=A15, 'Week 1'!$F$1, if('Week 1'!$K$1=A15, 'Week 1'!$P$1, if('Week 1'!$A$21=A15, 'Week 1'!$F$21, if('Week 1'!$K$21=A15, 'Week 1'!$P$21, if('Week 1'!$A$41=A15, 'Week 1'!$F$41, if('Week 1'!$K$41=A15, 'Week 1'!$P$41)))))) -> Loss | E16: =if('Week 1'!$A$1=A15, 'Week 1'!$I$1, if('Week 1'!$K$1=A15, 'Week 1'!$S$1, if('Week 1'!$A$21=A15, 'Week 1'!$I$21, if('Week 1'!$K$21=A15, 'Week 1'!$S$21, if('Week 1'!$A$41=A15, 'Week 1'!$I$41, if('Week 1'!$K$41=A15, 'Week 1'!$S$41)))))) -> -23 | G16: Game 1 | H16: =VLOOKUP(G15, 'Full Schedule'!$A$3:$B$9, 2, False) -> Gargantuan | I16: =if(match(G15, 'Full Schedule'!$A$3:$A$8, 0)<4, "Home", "Away") -> Home | J16: =if('Week 1'!$A$1=G15, 'Week 1'!$F$1, if('Week 1'!$K$1=G15, 'Week 1'!$P$1, if('Week 1'!$A$21=G15, 'Week 1'!$F$21, if('Week 1'!$K$21=G15, 'Week 1'!$P$21, if('Week 1'!$A$41=G15, 'Week 1'!$F$41, if('Week 1'!$K$41=G15, 'Week 1'!$P$41)))))) -> Win | K16: =if('Week 1'!$A$1=G15, 'Week 1'!$I$1, if('Week 1'!$K$1=G15, 'Week 1'!$S$1, if('Week 1'!$A$21=G15, 'Week 1'!$I$21, if('Week 1'!$K$21=G15, 'Week 1'!$S$21, if('Week 1'!$A$41=G15, 'Week 1'!$I$41, if('Week 1'!$K$41=G15, 'Week 1'!$S$41)))))) -> 1
A17: Game 2 | B17: =vlookup(A15, 'Full Schedule'!$C$3:$D$8, 2, False) -> Migos | C17: =if(match(A15, 'Full Schedule'!$C$3:$C$8, 0)<4, "Home", "Away") -> Home | D17: =if('Week 2'!$A$1=A15, 'Week 2'!$F$1, if('Week 2'!$K$1=A15, 'Week 2'!$P$1, if('Week 2'!$A$21=A15, 'Week 2'!$F$21, if('Week 2'!$K$21=A15, 'Week 2'!$P$21, if('Week 2'!$A$41=A15, 'Week 2'!$F$41, if('Week 2'!$K$41=A15, 'Week 2'!$P$41)))))) -> Loss | E17: =if('Week 2'!$A$1=A15, 'Week 2'!$I$1, if('Week 2'!$K$1=A15, 'Week 2'!$S$1, if('Week 2'!$A$21=A15, 'Week 2'!$I$21, if('Week 2'!$K$21=A15, 'Week 2'!$S$21, if('Week 2'!$A$41=A15, 'Week 2'!$I$41, if('Week 2'!$K$41=A15, 'Week 2'!$S$41)))))) -> -22 | G17: Game 2 | H17: =vlookup(G15, 'Full Schedule'!$C$3:$D$8, 2, False) -> Team F | I17: =if(match(G15, 'Full Schedule'!$C$3:$C$8, 0)<4, "Home", "Away") -> Home | J17: =if('Week 2'!$A$1=G15, 'Week 2'!$F$1, if('Week 2'!$K$1=G15, 'Week 2'!$P$1, if('Week 2'!$A$21=G15, 'Week 2'!$F$21, if('Week 2'!$K$21=G15, 'Week 2'!$P$21, if('Week 2'!$A$41=G15, 'Week 2'!$F$41, if('Week 2'!$K$41=G15, 'Week 2'!$P$41)))))) -> Loss | K17: =if('Week 2'!$A$1=G15, 'Week 2'!$I$1, if('Week 2'!$K$1=G15, 'Week 2'!$S$1, if('Week 2'!$A$21=G15, 'Week 2'!$I$21, if('Week 2'!$K$21=G15, 'Week 2'!$S$21, if('Week 2'!$A$41=G15, 'Week 2'!$I$41, if('Week 2'!$K$41=G15, 'Week 2'!$S$41)))))) -> -2
A18: Game 3 | B18: =vlookup(A15, 'Full Schedule'!$E$3:$F$8, 2, False) -> Team E | C18: =if(match(A15, 'Full Schedule'!$E$3:$E$8, 0)<4, "Home", "Away") -> Home | D18: =if('Week 3'!$A$1=A15, 'Week 3'!$F$1, if('Week 3'!$K$1=A15, 'Week 3'!$P$1, if('Week 3'!$A$21=A15, 'Week 3'!$F$21, if('Week 3'!$K$21=A15, 'Week 3'!$P$21, if('Week 3'!$A$41=A15, 'Week 3'!$F$41, if('Week 3'!$K$41=A15, 'Week 3'!$P$41)))))) -> Win | E18: =if('Week 3'!$A$1=A15, 'Week 3'!$I$1, if('Week 3'!$K$1=A15, 'Week 3'!$S$1, if('Week 3'!$A$21=A15, 'Week 3'!$I$21, if('Week 3'!$K$21=A15, 'Week 3'!$S$21, if('Week 3'!$A$41=A15, 'Week 3'!$I$41, if('Week 3'!$K$41=A15, 'Week 3'!$S$41)))))) -> 1 | G18: Game 3 | H18: =vlookup(G15, 'Full Schedule'!$E$3:$F$8, 2, False) -> Team C | I18: =if(match(G15, 'Full Schedule'!$E$3:$E$8, 0)<4, "Home", "Away") -> Away | J18: =if('Week 3'!$A$1=G15, 'Week 3'!$F$1, if('Week 3'!$K$1=G15, 'Week 3'!$P$1, if('Week 3'!$A$21=G15, 'Week 3'!$F$21, if('Week 3'!$K$21=G15, 'Week 3'!$P$21, if('Week 3'!$A$41=G15, 'Week 3'!$F$41, if('Week 3'!$K$41=G15, 'Week 3'!$P$41)))))) -> Loss | K18: =if('Week 3'!$A$1=G15, 'Week 3'!$I$1, if('Week 3'!$K$1=G15, 'Week 3'!$S$1, if('Week 3'!$A$21=G15, 'Week 3'!$I$21, if('Week 3'!$K$21=G15, 'Week 3'!$S$21, if('Week 3'!$A$41=G15, 'Week 3'!$I$41, if('Week 3'!$K$41=G15, 'Week 3'!$S$41)))))) -> -1
A19: Game 4 | B19: =vlookup(A15, 'Full Schedule'!$G$3:$H$8, 2, False) -> Team E | C19: =if(match(A15, 'Full Schedule'!$G$3:$G$8, 0)<4, "Home", "Away") -> Away | D19: =if('Week 4'!$A$1=A15, 'Week 4'!$F$1, if('Week 4'!$K$1=A15, 'Week 4'!$P$1, if('Week 4'!$A$21=A15, 'Week 4'!$F$21, if('Week 4'!$K$21=A15, 'Week 4'!$P$21, if('Week 4'!$A$41=A15, 'Week 4'!$F$41, if('Week 4'!$K$41=A15, 'Week 4'!$P$41)))))) -> Loss | E19: =if('Week 4'!$A$1=A15, 'Week 4'!$I$1, if('Week 4'!$K$1=A15, 'Week 4'!$S$1, if('Week 4'!$A$21=A15, 'Week 4'!$I$21, if('Week 4'!$K$21=A15, 'Week 4'!$S$21, if('Week 4'!$A$41=A15, 'Week 4'!$I$41, if('Week 4'!$K$41=A15, 'Week 4'!$S$41)))))) -> -3 | G19: Game 4 | H19: =vlookup(G15, 'Full Schedule'!$G$3:$H$8, 2, False) -> Team C | I19: =if(match(G15, 'Full Schedule'!$G$3:$G$8, 0)<4, "Home", "Away") -> Home | J19: =if('Week 4'!$A$1=G15, 'Week 4'!$F$1, if('Week 4'!$K$1=G15, 'Week 4'!$P$1, if('Week 4'!$A$21=G15, 'Week 4'!$F$21, if('Week 4'!$K$21=G15, 'Week 4'!$P$21, if('Week 4'!$A$41=G15, 'Week 4'!$F$41, if('Week 4'!$K$41=G15, 'Week 4'!$P$41)))))) -> Win | K19: =if('Week 4'!$A$1=G15, 'Week 4'!$I$1, if('Week 4'!$K$1=G15, 'Week 4'!$S$1, if('Week 4'!$A$21=G15, 'Week 4'!$I$21, if('Week 4'!$K$21=G15, 'Week 4'!$S$21, if('Week 4'!$A$41=G15, 'Week 4'!$I$41, if('Week 4'!$K$41=G15, 'Week 4'!$S$41)))))) -> 3
A20: Game 5 | B20: =vlookup(A15, 'Full Schedule'!$I$3:$J$8, 2, False) -> Team F | C20: =if(match(A15, 'Full Schedule'!$I$3:$I$8, 0)<4, "Home", "Away") -> Home | D20: =if('Week 5'!$A$1=A15, 'Week 5'!$F$1, if('Week 5'!$K$1=A15, 'Week 5'!$P$1, if('Week 5'!$A$21=A15, 'Week 5'!$F$21, if('Week 5'!$K$21=A15, 'Week 5'!$P$21, if('Week 5'!$A$41=A15, 'Week 5'!$F$41, if('Week 5'!$K$41=A15, 'Week 5'!$P$41)))))) -> Win | E20: =if('Week 5'!$A$1=A15, 'Week 5'!$I$1, if('Week 5'!$K$1=A15, 'Week 5'!$S$1, if('Week 5'!$A$21=A15, 'Week 5'!$I$21, if('Week 5'!$K$21=A15, 'Week 5'!$S$21, if('Week 5'!$A$41=A15, 'Week 5'!$I$41, if('Week 5'!$K$41=A15, 'Week 5'!$S$41)))))) -> 4 | G20: Game 5 | H20: =vlookup(G15, 'Full Schedule'!$I$3:$J$8, 2, False) -> Candice? | I20: =if(match(G15, 'Full Schedule'!$I$3:$I$8, 0)<4, "Home", "Away") -> Away | J20: =if('Week 5'!$A$1=G15, 'Week 5'!$F$1, if('Week 5'!$K$1=G15, 'Week 5'!$P$1, if('Week 5'!$A$21=G15, 'Week 5'!$F$21, if('Week 5'!$K$21=G15, 'Week 5'!$P$21, if('Week 5'!$A$41=G15, 'Week 5'!$F$41, if('Week 5'!$K$41=G15, 'Week 5'!$P$41)))))) -> Win | K20: =if('Week 5'!$A$1=G15, 'Week 5'!$I$1, if('Week 5'!$K$1=G15, 'Week 5'!$S$1, if('Week 5'!$A$21=G15, 'Week 5'!$I$21, if('Week 5'!$K$21=G15, 'Week 5'!$S$21, if('Week 5'!$A$41=G15, 'Week 5'!$I$41, if('Week 5'!$K$41=G15, 'Week 5'!$S$41)))))) -> 1
A21: Game 6 | B21: =vlookup(A15, 'Full Schedule'!$K$3:$L$8, 2, False) -> Gargantuan | C21: =if(match(A15, 'Full Schedule'!$K$3:$K$8, 0)<4, "Home", "Away") -> Away | D21: =if('Week 6'!$A$1=A15, 'Week 6'!$F$1, if('Week 6'!$K$1=A15, 'Week 6'!$P$1, if('Week 6'!$A$21=A15, 'Week 6'!$F$21, if('Week 6'!$K$21=A15, 'Week 6'!$P$21, if('Week 6'!$A$41=A15, 'Week 6'!$F$41, if('Week 6'!K$41=A15, 'Week 6'!$P$41)))))) -> Loss | E21: =if('Week 6'!$A$1=A15, 'Week 6'!$I$1, if('Week 6'!$K$1=A15, 'Week 6'!$S$1, if('Week 6'!$A$21=A15, 'Week 6'!$I$21, if('Week 6'!$K$21=A15, 'Week 6'!$S$21, if('Week 6'!$A$41=A15, 'Week 6'!$I$41, if('Week 6'!$K$41=A15, 'Week 6'!$S$41)))))) -> -6 | G21: Game 6 | H21: =vlookup(G15, 'Full Schedule'!$K$3:$L$8, 2, False) -> Team F | I21: =if(match(G15, 'Full Schedule'!$K$3:$K$8, 0)<4, "Home", "Away") -> Away | J21: =if('Week 6'!$A$1=G15, 'Week 6'!$F$1, if('Week 6'!$K$1=G15, 'Week 6'!$P$1, if('Week 6'!$A$21=G15, 'Week 6'!$F$21, if('Week 6'!$K$21=G15, 'Week 6'!$P$21, if('Week 6'!$A$41=G15, 'Week 6'!$F$41, if('Week 6'!$K$41=G15, 'Week 6'!$P$41)))))) -> Loss | K21: =if('Week 6'!$A$1=G15, 'Week 6'!$I$1, if('Week 6'!$K$1=G15, 'Week 6'!$S$1, if('Week 6'!$A$21=G15, 'Week 6'!$I$21, if('Week 6'!$K$21=G15, 'Week 6'!$S$21, if('Week 6'!$A$41=G15, 'Week 6'!$I$41, if('Week 6'!$K$41=G15, 'Week 6'!$S$41)))))) -> -2
A22: Game 7 | B22: =vlookup(A15, 'Full Schedule'!$M$3:$N$8, 2, False) -> Candice? | C22: Split | D22: =if('Week 7'!$A$1=A15, 'Week 7'!$F14, if('Week 7'!$K$1=A15, 'Week 7'!$P$1, if('Week 7'!$A$21=A15, 'Week 7'!$F$21, if('Week 7'!$K$21=A15, 'Week 7'!$P$21, if('Week 7'!$A$41=A15, 'Week 7'!$F$41, if('Week 7'!$K$41=A15, 'Week 7'!$P$41)))))) -> Win | E22: =if('Week 7'!$A$1=A15, 'Week 7'!$I$1, if('Week 7'!$K$1=A15, 'Week 7'!$S$1, if('Week 7'!$A$21=A15, 'Week 7'!$I$21, if('Week 7'!$K$21=A15, 'Week 7'!$S$21, if('Week 7'!$A$41=A15, 'Week 7'!$I$41, if('Week 7'!$K$41=A15, 'Week 7'!$S$41)))))) -> 9 | G22: Game 7 | H22: =vlookup(G15, 'Full Schedule'!$M$3:$N$8, 2, False) -> Migos | I22: Split | J22: =if('Week 7'!$A$1=G15, 'Week 7'!$F14, if('Week 7'!$K$1=G15, 'Week 7'!$P$1, if('Week 7'!$A$21=G15, 'Week 7'!$F$21, if('Week 7'!$K$21=G15, 'Week 7'!$P$21, if('Week 7'!$A$41=G15, 'Week 7'!$F$41, if('Week 7'!$K$41=G15, 'Week 7'!$P$41)))))) | K22: =if('Week 7'!$A$1=G15, 'Week 7'!$I$1, if('Week 7'!$K$1=G15, 'Week 7'!$S$1, if('Week 7'!$A$21=G15, 'Week 7'!$I$21, if('Week 7'!$K$21=G15, 'Week 7'!$S$21, if('Week 7'!$A$41=G15, 'Week 7'!$I$41, if('Week 7'!$K$41=G15, 'Week 7'!$S$41)))))) -> -3
A25: Total | D25: =iferror(countif(D16:D22, "Win")/(countif(D16:D22, "Win")+countif(D16:D22, "Loss")), "") -> 0.42857143 | E25: =SUM(E16:E24) -> -40 | G25: Total | J25: =iferror(countif(J16:J22, "Win")/(countif(J16:J22, "Win")+countif(J16:J22, "Loss")), "") -> 0.5 | K25: =SUM(K16:K24) -> -3
A27: =Draft!F25 -> Arnav | G27: =Draft!G25 -> Jay
A28: =Draft!F24 -> Migos | B28: Opponent | C28: Home/Away | D28: Result | E28: Margin | G28: =Draft!G24 -> Team F | H28: Opponent | I28: Home/Away | J28: Result | K28: Margin
A29: Game 1 | B29: =VLOOKUP(A28, 'Full Schedule'!$A$3:$B$9, 2, False) -> Candice? | C29: =if(match(A28, 'Full Schedule'!$A$3:$A$8, 0)<4, "Home", "Away") -> Away | D29: =if('Week 1'!$A$1=A28, 'Week 1'!$F$1, if('Week 1'!$K$1=A28, 'Week 1'!$P$1, if('Week 1'!$A$21=A28, 'Week 1'!$F$21, if('Week 1'!$K$21=A28, 'Week 1'!$P$21, if('Week 1'!$A$41=A28, 'Week 1'!$F$41, if('Week 1'!$K$41=A28, 'Week 1'!$P$41)))))) -> Loss | E29: =if('Week 1'!$A$1=A28, 'Week 1'!$I$1, if('Week 1'!$K$1=A28, 'Week 1'!$S$1, if('Week 1'!$A$21=A28, 'Week 1'!$I$21, if('Week 1'!$K$21=A28, 'Week 1'!$S$21, if('Week 1'!$A$41=A28, 'Week 1'!$I$41, if('Week 1'!$K$41=A28, 'Week 1'!$S$41)))))) -> -11 | G29: Game 1 | H29: =VLOOKUP(G28, 'Full Schedule'!$A$3:$B$9, 2, False) -> Team C | I29: =if(match(G28, 'Full Schedule'!$A$3:$A$8, 0)<4, "Home", "Away") -> Home | J29: =if('Week 1'!$A$1=G28, 'Week 1'!$F$1, if('Week 1'!$K$1=G28, 'Week 1'!$P$1, if('Week 1'!$A$21=G28, 'Week 1'!$F$21, if('Week 1'!$K$21=G28, 'Week 1'!$P$21, if('Week 1'!$A$41=G28, 'Week 1'!$F$41, if('Week 1'!$K$41=G28, 'Week 1'!$P$41)))))) -> Win | K29: =if('Week 1'!$A$1=G28, 'Week 1'!$I$1, if('Week 1'!$K$1=G28, 'Week 1'!$S$1, if('Week 1'!$A$21=G28, 'Week 1'!$I$21, if('Week 1'!$K$21=G28, 'Week 1'!$S$21, if('Week 1'!$A$41=G28, 'Week 1'!$I$41, if('Week 1'!$K$41=G28, 'Week 1'!$S$41)))))) -> 23
A30: Game 2 | B30: =vlookup(A28, 'Full Schedule'!$C$3:$D$8, 2, False) -> Team C | C30: =if(match(A28, 'Full Schedule'!$C$3:$C$8, 0)<4, "Home", "Away") -> Away | D30: =if('Week 2'!$A$1=A28, 'Week 2'!$F$1, if('Week 2'!$K$1=A28, 'Week 2'!$P$1, if('Week 2'!$A$21=A28, 'Week 2'!$F$21, if('Week 2'!$K$21=A28, 'Week 2'!$P$21, if('Week 2'!$A$41=A28, 'Week 2'!$F$41, if('Week 2'!$K$41=A28, 'Week 2'!$P$41)))))) -> Win | E30: =if('Week 2'!$A$1=A28, 'Week 2'!$I$1, if('Week 2'!$K$1=A28, 'Week 2'!$S$1, if('Week 2'!$A$21=A28, 'Week 2'!$I$21, if('Week 2'!$K$21=A28, 'Week 2'!$S$21, if('Week 2'!$A$41=A28, 'Week 2'!$I$41, if('Week 2'!$K$41=A28, 'Week 2'!$S$41)))))) -> 22 | G30: Game 2 | H30: =vlookup(G28, 'Full Schedule'!$C$3:$D$8, 2, False) -> Team E | I30: =if(match(G28, 'Full Schedule'!$C$3:$C$8, 0)<4, "Home", "Away") -> Away | J30: =if('Week 2'!$A$1=G28, 'Week 2'!$F$1, if('Week 2'!$K$1=G28, 'Week 2'!$P$1, if('Week 2'!$A$21=G28, 'Week 2'!$F$21, if('Week 2'!$K$21=G28, 'Week 2'!$P$21, if('Week 2'!$A$41=G28, 'Week 2'!$F$41, if('Week 2'!$K$41=G28, 'Week 2'!$P$41)))))) -> Win | K30: =if('Week 2'!$A$1=G28, 'Week 2'!$I$1, if('Week 2'!$K$1=G28, 'Week 2'!$S$1, if('Week 2'!$A$21=G28, 'Week 2'!$I$21, if('Week 2'!$K$21=G28, 'Week 2'!$S$21, if('Week 2'!$A$41=G28, 'Week 2'!$I$41, if('Week 2'!$K$41=G28, 'Week 2'!$S$41)))))) -> 2
A31: Game 3 | B31: =vlookup(A28, 'Full Schedule'!$E$3:$F$8, 2, False) -> Gargantuan | C31: =if(match(A28, 'Full Schedule'!$E$3:$E$8, 0)<4, "Home", "Away") -> Home | D31: =if('Week 3'!$A$1=A28, 'Week 3'!$F$1, if('Week 3'!$K$1=A28, 'Week 3'!$P$1, if('Week 3'!$A$21=A28, 'Week 3'!$F$21, if('Week 3'!$K$21=A28, 'Week 3'!$P$21, if('Week 3'!$A$41=A28, 'Week 3'!$F$41, if('Week 3'!$K$41=A28, 'Week 3'!$P$41)))))) -> Win | E31: =if('Week 3'!$A$1=A28, 'Week 3'!$I$1, if('Week 3'!$K$1=A28, 'Week 3'!$S$1, if('Week 3'!$A$21=A28, 'Week 3'!$I$21, if('Week 3'!$K$21=A28, 'Week 3'!$S$21, if('Week 3'!$A$41=A28, 'Week 3'!$I$41, if('Week 3'!$K$41=A28, 'Week 3'!$S$41)))))) -> 6 | G31: Game 3 | H31: =vlookup(G28, 'Full Schedule'!$E$3:$F$8, 2, False) -> Candice? | I31: =if(match(G28, 'Full Schedule'!$E$3:$E$8, 0)<4, "Home", "Away") -> Home | J31: =if('Week 3'!$A$1=G28, 'Week 3'!$F$1, if('Week 3'!$K$1=G28, 'Week 3'!$P$1, if('Week 3'!$A$21=G28, 'Week 3'!$F$21, if('Week 3'!$K$21=G28, 'Week 3'!$P$21, if('Week 3'!$A$41=G28, 'Week 3'!$F$41, if('Week 3'!$K$41=G28, 'Week 3'!$P$41)))))) -> Loss | K31: =if('Week 3'!$A$1=G28, 'Week 3'!$I$1, if('Week 3'!$K$1=G28, 'Week 3'!$S$1, if('Week 3'!$A$21=G28, 'Week 3'!$I$21, if('Week 3'!$K$21=G28, 'Week 3'!$S$21, if('Week 3'!$A$41=G28, 'Week 3'!$I$41, if('Week 3'!$K$41=G28, 'Week 3'!$S$41)))))) -> -21
A32: Game 4 | B32: =vlookup(A28, 'Full Schedule'!$G$3:$H$8, 2, False) -> Team F | C32: =if(match(A28, 'Full Schedule'!$G$3:$G$8, 0)<4, "Home", "Away") -> Home | D32: =if('Week 4'!$A$1=A28, 'Week 4'!$F$1, if('Week 4'!$K$1=A28, 'Week 4'!$P$1, if('Week 4'!$A$21=A28, 'Week 4'!$F$21, if('Week 4'!$K$21=A28, 'Week 4'!$P$21, if('Week 4'!$A$41=A28, 'Week 4'!$F$41, if('Week 4'!$K$41=A28, 'Week 4'!$P$41)))))) -> Win | E32: =if('Week 4'!$A$1=A28, 'Week 4'!$I$1, if('Week 4'!$K$1=A28, 'Week 4'!$S$1, if('Week 4'!$A$21=A28, 'Week 4'!$I$21, if('Week 4'!$K$21=A28, 'Week 4'!$S$21, if('Week 4'!$A$41=A28, 'Week 4'!$I$41, if('Week 4'!$K$41=A28, 'Week 4'!$S$41)))))) -> 5 | G32: Game 4 | H32: =vlookup(G28, 'Full Schedule'!$G$3:$H$8, 2, False) -> Migos | I32: =if(match(G28, 'Full Schedule'!$G$3:$G$8, 0)<4, "Home", "Away") -> Away | J32: =if('Week 4'!$A$1=G28, 'Week 4'!$F$1, if('Week 4'!$K$1=G28, 'Week 4'!$P$1, if('Week 4'!$A$21=G28, 'Week 4'!$F$21, if('Week 4'!$K$21=G28, 'Week 4'!$P$21, if('Week 4'!$A$41=G28, 'Week 4'!$F$41, if('Week 4'!$K$41=G28, 'Week 4'!$P$41)))))) -> Loss | K32: =if('Week 4'!$A$1=G28, 'Week 4'!$I$1, if('Week 4'!$K$1=G28, 'Week 4'!$S$1, if('Week 4'!$A$21=G28, 'Week 4'!$I$21, if('Week 4'!$K$21=G28, 'Week 4'!$S$21, if('Week 4'!$A$41=G28, 'Week 4'!$I$41, if('Week 4'!$K$41=G28, 'Week 4'!$S$41)))))) -> -5
A33: Game 5 | B33: =vlookup(A28, 'Full Schedule'!$I$3:$J$8, 2, False) -> Gargantuan | C33: =if(match(A28, 'Full Schedule'!$I$3:$I$8, 0)<4, "Home", "Away") -> Away | D33: =if('Week 5'!$A$1=A28, 'Week 5'!$F$1, if('Week 5'!$K$1=A28, 'Week 5'!$P$1, if('Week 5'!$A$21=A28, 'Week 5'!$F$21, if('Week 5'!$K$21=A28, 'Week 5'!$P$21, if('Week 5'!$A$41=A28, 'Week 5'!$F$41, if('Week 5'!$K$41=A28, 'Week 5'!$P$41)))))) -> Win | E33: =if('Week 5'!$A$1=A28, 'Week 5'!$I$1, if('Week 5'!$K$1=A28, 'Week 5'!$S$1, if('Week 5'!$A$21=A28, 'Week 5'!$I$21, if('Week 5'!$K$21=A28, 'Week 5'!$S$21, if('Week 5'!$A$41=A28, 'Week 5'!$I$41, if('Week 5'!$K$41=A28, 'Week 5'!$S$41)))))) -> 5 | G33: Game 5 | H33: =vlookup(G28, 'Full Schedule'!$I$3:$J$8, 2, False) -> Team C | I33: =if(match(G28, 'Full Schedule'!$I$3:$I$8, 0)<4, "Home", "Away") -> Away | J33: =if('Week 5'!$A$1=G28, 'Week 5'!$F$1, if('Week 5'!$K$1=G28, 'Week 5'!$P$1, if('Week 5'!$A$21=G28, 'Week 5'!$F$21, if('Week 5'!$K$21=G28, 'Week 5'!$P$21, if('Week 5'!$A$41=G28, 'Week 5'!$F$41, if('Week 5'!$K$41=G28, 'Week 5'!$P$41)))))) -> Loss | K33: =if('Week 5'!$A$1=G28, 'Week 5'!$I$1, if('Week 5'!$K$1=G28, 'Week 5'!$S$1, if('Week 5'!$A$21=G28, 'Week 5'!$I$21, if('Week 5'!$K$21=G28, 'Week 5'!$S$21, if('Week 5'!$A$41=G28, 'Week 5'!$I$41, if('Week 5'!$K$41=G28, 'Week 5'!$S$41)))))) -> -4
A34: Game 6 | B34: =vlookup(A28, 'Full Schedule'!$K$3:$L$8, 2, False) -> Candice? | C34: =if(match(A28, 'Full Schedule'!$K$3:$K$8, 0)<4, "Home", "Away") -> Home | D34: =if('Week 6'!$A$1=A28, 'Week 6'!$F$1, if('Week 6'!$K$1=A28, 'Week 6'!$P$1, if('Week 6'!$A$21=A28, 'Week 6'!$F$21, if('Week 6'!$K$21=A28, 'Week 6'!$P$21, if('Week 6'!$A$41=A28, 'Week 6'!$F$41, if('Week 6'!K$41=A28, 'Week 6'!$P$41)))))) -> Win | E34: =if('Week 6'!$A$1=A28, 'Week 6'!$I$1, if('Week 6'!$K$1=A28, 'Week 6'!$S$1, if('Week 6'!$A$21=A28, 'Week 6'!$I$21, if('Week 6'!$K$21=A28, 'Week 6'!$S$21, if('Week 6'!$A$41=A28, 'Week 6'!$I$41, if('Week 6'!$K$41=A28, 'Week 6'!$S$41)))))) -> 1 | G34: Game 6 | H34: =vlookup(G28, 'Full Schedule'!$K$3:$L$8, 2, False) -> Team E | I34: =if(match(G28, 'Full Schedule'!$K$3:$K$8, 0)<4, "Home", "Away") -> Home | J34: =if('Week 6'!$A$1=G28, 'Week 6'!$F$1, if('Week 6'!$K$1=G28, 'Week 6'!$P$1, if('Week 6'!$A$21=G28, 'Week 6'!$F$21, if('Week 6'!$K$21=G28, 'Week 6'!$P$21, if('Week 6'!$A$41=G28, 'Week 6'!$F$41, if('Week 6'!$K$41=G28, 'Week 6'!$P$41)))))) -> Win | K34: =if('Week 6'!$A$1=G28, 'Week 6'!$I$1, if('Week 6'!$K$1=G28, 'Week 6'!$S$1, if('Week 6'!$A$21=G28, 'Week 6'!$I$21, if('Week 6'!$K$21=G28, 'Week 6'!$S$21, if('Week 6'!$A$41=G28, 'Week 6'!$I$41, if('Week 6'!$K$41=G28, 'Week 6'!$S$41)))))) -> 2
A35: Game 7 | B35: =vlookup(A28, 'Full Schedule'!$M$3:$N$8, 2, False) -> Team E | C35: Split | D35: =if('Week 7'!$A$1=A28, 'Week 7'!$F27, if('Week 7'!$K$1=A28, 'Week 7'!$P$1, if('Week 7'!$A$21=A28, 'Week 7'!$F$21, if('Week 7'!$K$21=A28, 'Week 7'!$P$21, if('Week 7'!$A$41=A28, 'Week 7'!$F$41, if('Week 7'!$K$41=A28, 'Week 7'!$P$41)))))) -> Win | E35: =if('Week 7'!$A$1=A28, 'Week 7'!$I$1, if('Week 7'!$K$1=A28, 'Week 7'!$S$1, if('Week 7'!$A$21=A28, 'Week 7'!$I$21, if('Week 7'!$K$21=A28, 'Week 7'!$S$21, if('Week 7'!$A$41=A28, 'Week 7'!$I$41, if('Week 7'!$K$41=A28, 'Week 7'!$S$41)))))) -> 3 | G35: Game 7 | H35: =vlookup(G28, 'Full Schedule'!$M$3:$N$8, 2, False) -> Gargantuan | I35: Split | J35: =if('Week 7'!$A$1=G28, 'Week 7'!$F27, if('Week 7'!$K$1=G28, 'Week 7'!$P$1, if('Week 7'!$A$21=G28, 'Week 7'!$F$21, if('Week 7'!$K$21=G28, 'Week 7'!$P$21, if('Week 7'!$A$41=G28, 'Week 7'!$F$41, if('Week 7'!$K$41=G28, 'Week 7'!$P$41)))))) -> Loss | K35: =if('Week 7'!$A$1=G28, 'Week 7'!$I$1, if('Week 7'!$K$1=G28, 'Week 7'!$S$1, if('Week 7'!$A$21=G28, 'Week 7'!$I$21, if('Week 7'!$K$21=G28, 'Week 7'!$S$21, if('Week 7'!$A$41=G28, 'Week 7'!$I$41, if('Week 7'!$K$41=G28, 'Week 7'!$S$41)))))) -> -1
A38: Total | D38: =iferror(countif(D29:D35, "Win")/(countif(D29:D35, "Win")+countif(D29:D35, "Loss")), "") -> 0.85714286 | E38: =SUM(E29:E37) -> 31 | G38: Total | J38: =iferror(countif(J29:J35, "Win")/(countif(J29:J35, "Win")+countif(J29:J35, "Loss")), "") -> 0.42857143 | K38: =SUM(K29:K37) -> -4

Sheet Full Schedule
A1: Home | B1: Away | C1: Home | D1: Away | E1: Home | F1: Away | G1: Home | H1: Away | I1: Home | J1: Away | K1: Home | L1: Away | M1: Home | N1: Away
A2: Week 1 | C2: Week 2 | E2: Week 3 | G2: Week 4 | I2: Week 5 | K2: Week 6 | M2: Week 7
A3: Candice? | B3: Migos | C3: Team C | D3: Migos | E3: Migos | F3: Gargantuan | G3: Migos | H3: Team F | I3: Gargantuan | J3: Migos | K3: Migos | L3: Candice? | M3: Team E | N3: Migos
A4: Team F | B4: Team C | C4: Gargantuan | D4: Candice? | E4: Team F | F4: Candice? | G4: Candice? | H4: Gargantuan | I4: Candice? | J4: Team E | K4: Gargantuan | L4: Team C | M4: Candice? | N4: Team C
A5: Team E | B5: Gargantuan | C5: Team E | D5: Team F | E5: Team C | F5: Team E | G5: Team E | H5: Team C | I5: Team C | J5: Team F | K5: Team F | L5: Team E | M5: Gargantuan | N5: Team F
A6: =B3 -> Migos | B6: =A3 -> Candice? | C6: =D3 -> Migos | D6: =C3 -> Team C | E6: =F3 -> Gargantuan | F6: =E3 -> Migos | G6: =H3 -> Team F | H6: =G3 -> Migos | I6: =J3 -> Migos | J6: =I3 -> Gargantuan | K6: =L3 -> Candice? | L6: =K3 -> Migos | M6: =N3 -> Migos | N6: =M3 -> Team E
A7: =B4 -> Team C | B7: =A4 -> Team F | C7: =D4 -> Candice? | D7: =C4 -> Gargantuan | E7: =F4 -> Candice? | F7: =E4 -> Team F | G7: =H4 -> Gargantuan | H7: =G4 -> Candice? | I7: =J4 -> Team E | J7: =I4 -> Candice? | K7: =L4 -> Team C | L7: =K4 -> Gargantuan | M7: =N4 -> Team C | N7: =M4 -> Candice?
A8: =B5 -> Gargantuan | B8: =A5 -> Team E | C8: =D5 -> Team F | D8: =C5 -> Team E | E8: =F5 -> Team E | F8: =E5 -> Team C | G8: =H5 -> Team C | H8: =G5 -> Team E | I8: =J5 -> Team F | J8: =I5 -> Team C | K8: =L5 -> Team E | L8: =K5 -> Team F | M8: =N5 -> Team F | N8: =M5 -> Gargantuan
A11: =if('Week 1'!$A$1=A3, 'Week 1'!$F$1, if('Week 1'!$K$1=A3, 'Week 1'!$P$1, if('Week 1'!$A$21=A3, 'Week 1'!$F$21, if('Week 1'!$K$21=A3, 'Week 1'!$P$21, if('Week 1'!$A$41=A3, 'Week 1'!$F$41, if('Week 1'!$K$41=A3, 'Week 1'!$P$41)))))) -> Win | B11: =if('Week 1'!$A$1=B3, 'Week 1'!$F$1, if('Week 1'!$K$1=B3, 'Week 1'!$P$1, if('Week 1'!$A$21=B3, 'Week 1'!$F$21, if('Week 1'!$K$21=B3, 'Week 1'!$P$21, if('Week 1'!$A$41=B3, 'Week 1'!$F$41, if('Week 1'!$K$41=B3, 'Week 1'!$P$41)))))) -> Loss | C11: =if('Week 2'!$A$1=C3, 'Week 2'!$F$1, if('Week 2'!$K$1=C3, 'Week 2'!$P$1, if('Week 2'!$A$21=C3, 'Week 2'!$F$21, if('Week 2'!$K$21=C3, 'Week 2'!$P$21, if('Week 2'!$A$41=C3, 'Week 2'!$F$41, if('Week 2'!$K$41=C3, 'Week 2'!$P$41)))))) -> Loss | D11: =if('Week 2'!$A$1=D3, 'Week 2'!$F$1, if('Week 2'!$K$1=D3, 'Week 2'!$P$1, if('Week 2'!$A$21=D3, 'Week 2'!$F$21, if('Week 2'!$K$21=D3, 'Week 2'!$P$21, if('Week 2'!$A$41=D3, 'Week 2'!$F$41, if('Week 2'!$K$41=D3, 'Week 2'!$P$41)))))) -> Win | E11: =if('Week 3'!$A$1=E3, 'Week 3'!$F$1, if('Week 3'!$K$1=E3, 'Week 3'!$P$1, if('Week 3'!$A$21=E3, 'Week 3'!$F$21, if('Week 3'!$K$21=E3, 'Week 3'!$P$21, if('Week 3'!$A$41=E3, 'Week 3'!$F$41, if('Week 3'!$K$41=E3, 'Week 3'!$P$41)))))) -> Win | F11: =if('Week 3'!$A$1=F3, 'Week 3'!$F$1, if('Week 3'!$K$1=F3, 'Week 3'!$P$1, if('Week 3'!$A$21=F3, 'Week 3'!$F$21, if('Week 3'!$K$21=F3, 'Week 3'!$P$21, if('Week 3'!$A$41=F3, 'Week 3'!$F$41, if('Week 3'!$K$41=F3, 'Week 3'!$P$41)))))) -> Loss | G11: =if('Week 4'!$A$1=G3, 'Week 4'!$F$1, if('Week 4'!$K$1=G3, 'Week 4'!$P$1, if('Week 4'!$A$21=G3, 'Week 4'!$F$21, if('Week 4'!$K$21=G3, 'Week 4'!$P$21, if('Week 4'!$A$41=G3, 'Week 4'!$F$41, if('Week 4'!$K$41=G3, 'Week 4'!$P$41)))))) -> Win | H11: =if('Week 4'!$A$1=H3, 'Week 4'!$F$1, if('Week 4'!$K$1=H3, 'Week 4'!$P$1, if('Week 4'!$A$21=H3, 'Week 4'!$F$21, if('Week 4'!$K$21=H3, 'Week 4'!$P$21, if('Week 4'!$A$41=H3, 'Week 4'!$F$41, if('Week 4'!$K$41=H3, 'Week 4'!$P$41)))))) -> Loss | I11: =if('Week 5'!$A$1=I3, 'Week 5'!$F$1, if('Week 5'!$K$1=I3, 'Week 5'!$P$1, if('Week 5'!$A$21=I3, 'Week 5'!$F$21, if('Week 5'!$K$21=I3, 'Week 5'!$P$21, if('Week 5'!$A$41=I3, 'Week 5'!$F$41, if('Week 5'!$K$41=I3, 'Week 5'!$P$41)))))) -> Loss | J11: =if('Week 5'!$A$1=J3, 'Week 5'!$F$1, if('Week 5'!$K$1=J3, 'Week 5'!$P$1, if('Week 5'!$A$21=J3, 'Week 5'!$F$21, if('Week 5'!$K$21=J3, 'Week 5'!$P$21, if('Week 5'!$A$41=J3, 'Week 5'!$F$41, if('Week 5'!$K$41=J3, 'Week 5'!$P$41)))))) -> Win | K11: =if('Week 6'!$A$1=K3, 'Week 6'!$F$1, if('Week 6'!$K$1=K3, 'Week 6'!$P$1, if('Week 6'!$A$21=K3, 'Week 6'!$F$21, if('Week 6'!$K$21=K3, 'Week 6'!$P$21, if('Week 6'!$A$41=K3, 'Week 6'!$F$41, if('Week 6'!$K$41=K3, 'Week 6'!$P$41)))))) -> Win | L11: =if('Week 6'!$A$1=L3, 'Week 6'!$F$1, if('Week 6'!$K$1=L3, 'Week 6'!$P$1, if('Week 6'!$A$21=L3, 'Week 6'!$F$21, if('Week 6'!$K$21=L3, 'Week 6'!$P$21, if('Week 6'!$A$41=L3, 'Week 6'!$F$41, if('Week 6'!$K$41=L3, 'Week 6'!$P$41)))))) -> Loss | M11: =if('Week 7'!$A$1=M3, 'Week 7'!$F$1, if('Week 7'!$K$1=M3, 'Week 7'!$P$1, if('Week 7'!$A$21=M3, 'Week 7'!$F$21, if('Week 7'!$K$21=M3, 'Week 7'!$P$21, if('Week 7'!$A$41=M3, 'Week 7'!$F$41, if('Week 7'!$K$41=M3, 'Week 7'!$P$41)))))) -> Loss | N11: =if('Week 7'!$A$1=N3, 'Week 7'!$F$1, if('Week 7'!$K$1=N3, 'Week 7'!$P$1, if('Week 7'!$A$21=N3, 'Week 7'!$F$21, if('Week 7'!$K$21=N3, 'Week 7'!$P$21, if('Week 7'!$A$41=N3, 'Week 7'!$F$41, if('Week 7'!$K$41=N3, 'Week 7'!$P$41)))))) -> Win
A12: =if('Week 1'!$A$1=A4, 'Week 1'!$F$1, if('Week 1'!$K$1=A4, 'Week 1'!$P$1, if('Week 1'!$A$21=A4, 'Week 1'!$F$21, if('Week 1'!$K$21=A4, 'Week 1'!$P$21, if('Week 1'!$A$41=A4, 'Week 1'!$F$41, if('Week 1'!$K$41=A4, 'Week 1'!$P$41)))))) -> Win | B12: =if('Week 1'!$A$1=B4, 'Week 1'!$F$1, if('Week 1'!$K$1=B4, 'Week 1'!$P$1, if('Week 1'!$A$21=B4, 'Week 1'!$F$21, if('Week 1'!$K$21=B4, 'Week 1'!$P$21, if('Week 1'!$A$41=B4, 'Week 1'!$F$41, if('Week 1'!$K$41=B4, 'Week 1'!$P$41)))))) -> Loss | C12: =if('Week 2'!$A$1=C4, 'Week 2'!$F$1, if('Week 2'!$K$1=C4, 'Week 2'!$P$1, if('Week 2'!$A$21=C4, 'Week 2'!$F$21, if('Week 2'!$K$21=C4, 'Week 2'!$P$21, if('Week 2'!$A$41=C4, 'Week 2'!$F$41, if('Week 2'!$K$41=C4, 'Week 2'!$P$41)))))) -> Loss | D12: =if('Week 2'!$A$1=D4, 'Week 2'!$F$1, if('Week 2'!$K$1=D4, 'Week 2'!$P$1, if('Week 2'!$A$21=D4, 'Week 2'!$F$21, if('Week 2'!$K$21=D4, 'Week 2'!$P$21, if('Week 2'!$A$41=D4, 'Week 2'!$F$41, if('Week 2'!$K$41=D4, 'Week 2'!$P$41)))))) -> Win | E12: =if('Week 3'!$A$1=E4, 'Week 3'!$F$1, if('Week 3'!$K$1=E4, 'Week 3'!$P$1, if('Week 3'!$A$21=E4, 'Week 3'!$F$21, if('Week 3'!$K$21=E4, 'Week 3'!$P$21, if('Week 3'!$A$41=E4, 'Week 3'!$F$41, if('Week 3'!$K$41=E4, 'Week 3'!$P$41)))))) -> Loss | F12: =if('Week 3'!$A$1=F4, 'Week 3'!$F$1, if('Week 3'!$K$1=F4, 'Week 3'!$P$1, if('Week 3'!$A$21=F4, 'Week 3'!$F$21, if('Week 3'!$K$21=F4, 'Week 3'!$P$21, if('Week 3'!$A$41=F4, 'Week 3'!$F$41, if('Week 3'!$K$41=F4, 'Week 3'!$P$41)))))) -> Win | G12: =if('Week 4'!$A$1=G4, 'Week 4'!$F$1, if('Week 4'!$K$1=G4, 'Week 4'!$P$1, if('Week 4'!$A$21=G4, 'Week 4'!$F$21, if('Week 4'!$K$21=G4, 'Week 4'!$P$21, if('Week 4'!$A$41=G4, 'Week 4'!$F$41, if('Week 4'!$K$41=G4, 'Week 4'!$P$41)))))) -> Loss | H12: =if('Week 4'!$A$1=H4, 'Week 4'!$F$1, if('Week 4'!$K$1=H4, 'Week 4'!$P$1, if('Week 4'!$A$21=H4, 'Week 4'!$F$21, if('Week 4'!$K$21=H4, 'Week 4'!$P$21, if('Week 4'!$A$41=H4, 'Week 4'!$F$41, if('Week 4'!$K$41=H4, 'Week 4'!$P$41)))))) -> Win | I12: =if('Week 5'!$A$1=I4, 'Week 5'!$F$1, if('Week 5'!$K$1=I4, 'Week 5'!$P$1, if('Week 5'!$A$21=I4, 'Week 5'!$F$21, if('Week 5'!$K$21=I4, 'Week 5'!$P$21, if('Week 5'!$A$41=I4, 'Week 5'!$F$41, if('Week 5'!$K$41=I4, 'Week 5'!$P$41)))))) -> Loss | J12: =if('Week 5'!$A$1=J4, 'Week 5'!$F$1, if('Week 5'!$K$1=J4, 'Week 5'!$P$1, if('Week 5'!$A$21=J4, 'Week 5'!$F$21, if('Week 5'!$K$21=J4, 'Week 5'!$P$21, if('Week 5'!$A$41=J4, 'Week 5'!$F$41, if('Week 5'!$K$41=J4, 'Week 5'!$P$41)))))) -> Win | K12: =if('Week 6'!$A$1=K4, 'Week 6'!$F$1, if('Week 6'!$K$1=K4, 'Week 6'!$P$1, if('Week 6'!$A$21=K4, 'Week 6'!$F$21, if('Week 6'!$K$21=K4, 'Week 6'!$P$21, if('Week 6'!$A$41=K4, 'Week 6'!$F$41, if('Week 6'!$K$41=K4, 'Week 6'!$P$41)))))) -> Win | L12: =if('Week 6'!$A$1=L4, 'Week 6'!$F$1, if('Week 6'!$K$1=L4, 'Week 6'!$P$1, if('Week 6'!$A$21=L4, 'Week 6'!$F$21, if('Week 6'!$K$21=L4, 'Week 6'!$P$21, if('Week 6'!$A$41=L4, 'Week 6'!$F$41, if('Week 6'!$K$41=L4, 'Week 6'!$P$41)))))) -> Loss | M12: =if('Week 7'!$A$1=M4, 'Week 7'!$F$1, if('Week 7'!$K$1=M4, 'Week 7'!$P$1, if('Week 7'!$A$21=M4, 'Week 7'!$F$21, if('Week 7'!$K$21=M4, 'Week 7'!$P$21, if('Week 7'!$A$41=M4, 'Week 7'!$F$41, if('Week 7'!$K$41=M4, 'Week 7'!$P$41)))))) -> Loss | N12: =if('Week 7'!$A$1=N4, 'Week 7'!$F$1, if('Week 7'!$K$1=N4, 'Week 7'!$P$1, if('Week 7'!$A$21=N4, 'Week 7'!$F$21, if('Week 7'!$K$21=N4, 'Week 7'!$P$21, if('Week 7'!$A$41=N4, 'Week 7'!$F$41, if('Week 7'!$K$41=N4, 'Week 7'!$P$41)))))) -> Win
A13: =if('Week 1'!$A$1=A5, 'Week 1'!$F$1, if('Week 1'!$K$1=A5, 'Week 1'!$P$1, if('Week 1'!$A$21=A5, 'Week 1'!$F$21, if('Week 1'!$K$21=A5, 'Week 1'!$P$21, if('Week 1'!$A$41=A5, 'Week 1'!$F$41, if('Week 1'!$K$41=A5, 'Week 1'!$P$41)))))) -> Win | B13: =if('Week 1'!$A$1=B5, 'Week 1'!$F$1, if('Week 1'!$K$1=B5, 'Week 1'!$P$1, if('Week 1'!$A$21=B5, 'Week 1'!$F$21, if('Week 1'!$K$21=B5, 'Week 1'!$P$21, if('Week 1'!$A$41=B5, 'Week 1'!$F$41, if('Week 1'!$K$41=B5, 'Week 1'!$P$41)))))) -> Loss | C13: =if('Week 2'!$A$1=C5, 'Week 2'!$F$1, if('Week 2'!$K$1=C5, 'Week 2'!$P$1, if('Week 2'!$A$21=C5, 'Week 2'!$F$21, if('Week 2'!$K$21=C5, 'Week 2'!$P$21, if('Week 2'!$A$41=C5, 'Week 2'!$F$41, if('Week 2'!$K$41=C5, 'Week 2'!$P$41)))))) -> Loss | D13: =if('Week 2'!$A$1=D5, 'Week 2'!$F$1, if('Week 2'!$K$1=D5, 'Week 2'!$P$1, if('Week 2'!$A$21=D5, 'Week 2'!$F$21, if('Week 2'!$K$21=D5, 'Week 2'!$P$21, if('Week 2'!$A$41=D5, 'Week 2'!$F$41, if('Week 2'!$K$41=D5, 'Week 2'!$P$41)))))) -> Win | E13: =if('Week 3'!$A$1=E5, 'Week 3'!$F$1, if('Week 3'!$K$1=E5, 'Week 3'!$P$1, if('Week 3'!$A$21=E5, 'Week 3'!$F$21, if('Week 3'!$K$21=E5, 'Week 3'!$P$21, if('Week 3'!$A$41=E5, 'Week 3'!$F$41, if('Week 3'!$K$41=E5, 'Week 3'!$P$41)))))) -> Win | F13: =if('Week 3'!$A$1=F5, 'Week 3'!$F$1, if('Week 3'!$K$1=F5, 'Week 3'!$P$1, if('Week 3'!$A$21=F5, 'Week 3'!$F$21, if('Week 3'!$K$21=F5, 'Week 3'!$P$21, if('Week 3'!$A$41=F5, 'Week 3'!$F$41, if('Week 3'!$K$41=F5, 'Week 3'!$P$41)))))) -> Loss | G13: =if('Week 4'!$A$1=G5, 'Week 4'!$F$1, if('Week 4'!$K$1=G5, 'Week 4'!$P$1, if('Week 4'!$A$21=G5, 'Week 4'!$F$21, if('Week 4'!$K$21=G5, 'Week 4'!$P$21, if('Week 4'!$A$41=G5, 'Week 4'!$F$41, if('Week 4'!$K$41=G5, 'Week 4'!$P$41)))))) -> Win | H13: =if('Week 4'!$A$1=H5, 'Week 4'!$F$1, if('Week 4'!$K$1=H5, 'Week 4'!$P$1, if('Week 4'!$A$21=H5, 'Week 4'!$F$21, if('Week 4'!$K$21=H5, 'Week 4'!$P$21, if('Week 4'!$A$41=H5, 'Week 4'!$F$41, if('Week 4'!$K$41=H5, 'Week 4'!$P$41)))))) -> Loss | I13: =if('Week 5'!$A$1=I5, 'Week 5'!$F$1, if('Week 5'!$K$1=I5, 'Week 5'!$P$1, if('Week 5'!$A$21=I5, 'Week 5'!$F$21, if('Week 5'!$K$21=I5, 'Week 5'!$P$21, if('Week 5'!$A$41=I5, 'Week 5'!$F$41, if('Week 5'!$K$41=I5, 'Week 5'!$P$41)))))) -> Win | J13: =if('Week 5'!$A$1=J5, 'Week 5'!$F$1, if('Week 5'!$K$1=J5, 'Week 5'!$P$1, if('Week 5'!$A$21=J5, 'Week 5'!$F$21, if('Week 5'!$K$21=J5, 'Week 5'!$P$21, if('Week 5'!$A$41=J5, 'Week 5'!$F$41, if('Week 5'!$K$41=J5, 'Week 5'!$P$41)))))) -> Loss | K13: =if('Week 6'!$A$1=K5, 'Week 6'!$F$1, if('Week 6'!$K$1=K5, 'Week 6'!$P$1, if('Week 6'!$A$21=K5, 'Week 6'!$F$21, if('Week 6'!$K$21=K5, 'Week 6'!$P$21, if('Week 6'!$A$41=K5, 'Week 6'!$F$41, if('Week 6'!$K$41=K5, 'Week 6'!$P$41)))))) -> Win | L13: =if('Week 6'!$A$1=L5, 'Week 6'!$F$1, if('Week 6'!$K$1=L5, 'Week 6'!$P$1, if('Week 6'!$A$21=L5, 'Week 6'!$F$21, if('Week 6'!$K$21=L5, 'Week 6'!$P$21, if('Week 6'!$A$41=L5, 'Week 6'!$F$41, if('Week 6'!$K$41=L5, 'Week 6'!$P$41)))))) -> Loss | M13: =if('Week 7'!$A$1=M5, 'Week 7'!$F$1, if('Week 7'!$K$1=M5, 'Week 7'!$P$1, if('Week 7'!$A$21=M5, 'Week 7'!$F$21, if('Week 7'!$K$21=M5, 'Week 7'!$P$21, if('Week 7'!$A$41=M5, 'Week 7'!$F$41, if('Week 7'!$K$41=M5, 'Week 7'!$P$41)))))) -> Win | N13: =if('Week 7'!$A$1=N5, 'Week 7'!$F$1, if('Week 7'!$K$1=N5, 'Week 7'!$P$1, if('Week 7'!$A$21=N5, 'Week 7'!$F$21, if('Week 7'!$K$21=N5, 'Week 7'!$P$21, if('Week 7'!$A$41=N5, 'Week 7'!$F$41, if('Week 7'!$K$41=N5, 'Week 7'!$P$41)))))) -> Loss

Sheet Player Season Stats
A1: Name | B1: Games Played | C1: Win % | D1: Adjusted FGM | E1: FGM | F1: Bottom | G1: Bottom ISO | H1: Top | I1: Top ISO | J1: Misses | K1: FG% | M1: Player Rating
A2: =Draft!B46 -> Tyler | B2: =iferror(vlookup($A2, 'Player Game Stats'!$A:$J, 2, False), "") -> 4 | C2: =iferror(vlookup($A2, 'Player Game Stats'!$A:$J, 3, False), "") -> 0.25 | D2: =iferror(1.2*I2+1.1*H2+1.05*G2+1*F2, "") -> 11.2 | E2: =iferror(vlookup($A2, 'Player Game Stats'!$A:$J, 4, False), "") -> 10.75 | F2: =iferror(vlookup($A2, 'Player Game Stats'!$A:$J, 5, False), "") -> 5.75 | G2: =iferror(vlookup($A2, 'Player Game Stats'!$A:$J, 6, False), "") -> 1 | H2: =iferror(vlookup($A2, 'Player Game Stats'!$A:$J, 7, False), "") -> 4 | I2: =IFERROR(vlookup($A2, 'Player Game Stats'!$A:$J, 8, False), "") -> 0 | J2: =iferror(vlookup($A2, 'Player Game Stats'!$A:$J, 9, False), "") -> 30.75 | K2: =iferror(vlookup($A2, 'Player Game Stats'!$A:$J, 10, False), "") -> 0.25903614 | L2: =K2*D2 -> 2.9012048 | M2: =iferror(L2*$L$75, "") -> 7.4747475
A3: =Draft!B48 -> Lucas | B3: =iferror(vlookup($A3, 'Player Game Stats'!$A:$J, 2, False), "") -> 6 | C3: =iferror(vlookup($A3, 'Player Game Stats'!$A:$J, 3, False), "") -> 0.33333333 | D3: =iferror(1.2*I3+1.1*H3+1.05*G3+1*F3, "") -> 19.216667 | E3: =iferror(vlookup($A3, 'Player Game Stats'!$A:$J, 4, False), "") -> 17.833333 | F3: =iferror(vlookup($A3, 'Player Game Stats'!$A:$J, 5, False), "") -> 5.1666667 | G3: =iferror(vlookup($A3, 'Player Game Stats'!$A:$J, 6, False), "") -> 1.3333333 | H3: =iferror(vlookup($A3, 'Player Game Stats'!$A:$J, 7, False), "") -> 9.5 | I3: =IFERROR(vlookup($A3, 'Player Game Stats'!$A:$J, 8, False), "") -> 1.8333333 | J3: =iferror(vlookup($A3, 'Player Game Stats'!$A:$J, 9, False), "") -> 26.666667 | K3: =iferror(vlookup($A3, 'Player Game Stats'!$A:$J, 10, False), "") -> 0.40074906 | L3: =K3*D3 -> 7.7010612 | M3: =iferror(L3*$L$75, "") -> 19.841235
A4: =Draft!B49 -> Porco | B4: =iferror(vlookup($A4, 'Player Game Stats'!$A:$J, 2, False), "") -> 6 | C4: =iferror(vlookup($A4, 'Player Game Stats'!$A:$J, 3, False), "") -> 0.33333333 | D4: =iferror(1.2*I4+1.1*H4+1.05*G4+1*F4, "") -> 13.075 | E4: =iferror(vlookup($A4, 'Player Game Stats'!$A:$J, 4, False), "") -> 12.166667 | F4: =iferror(vlookup($A4, 'Player Game Stats'!$A:$J, 5, False), "") -> 3.8333333 | G4: =iferror(vlookup($A4, 'Player Game Stats'!$A:$J, 6, False), "") -> 0.5 | H4: =iferror(vlookup($A4, 'Player Game Stats'!$A:$J, 7, False), "") -> 6.8333333 | I4: =IFERROR(vlookup($A4, 'Player Game Stats'!$A:$J, 8, False), "") -> 1 | J4: =iferror(vlookup($A4, 'Player Game Stats'!$A:$J, 9, False), "") -> 26.833333 | K4: =iferror(vlookup($A4, 'Player Game Stats'!$A:$J, 10, False), "") -> 0.31196581 | L4: =K4*D4 -> 4.078953 | M4: =iferror(L4*$L$75, "") -> 10.509132
A5: =Draft!B50 -> Andy Yu | B5: =iferror(vlookup($A5, 'Player Game Stats'!$A:$J, 2, False), "") -> 6 | C5: =iferror(vlookup($A5, 'Player Game Stats'!$A:$J, 3, False), "") -> 0.33333333 | D5: =iferror(1.2*I5+1.1*H5+1.05*G5+1*F5, "") -> 17.825 | E5: =iferror(vlookup($A5, 'Player Game Stats'!$A:$J, 4, False), "") -> 16.666667 | F5: =iferror(vlookup($A5, 'Player Game Stats'!$A:$J, 5, False), "") -> 5.8333333 | G5: =iferror(vlookup($A5, 'Player Game Stats'!$A:$J, 6, False), "") -> 2.1666667 | H5: =iferror(vlookup($A5, 'Player Game Stats'!$A:$J, 7, False), "") -> 6.8333333 | I5: =IFERROR(vlookup($A5, 'Player Game Stats'!$A:$J, 8, False), "") -> 1.8333333 | J5: =iferror(vlookup($A5, 'Player Game Stats'!$A:$J, 9, False), "") -> 27 | K5: =iferror(vlookup($A5, 'Player Game Stats'!$A:$J, 10, False), "") -> 0.38167939 | L5: =K5*D5 -> 6.8034351 | M5: =iferror(L5*$L$75, "") -> 17.528566
A6: =Draft!B51 -> Dli | B6: =iferror(vlookup($A6, 'Player Game Stats'!$A:$J, 2, False), "") -> 7 | C6: =iferror(vlookup($A6, 'Player Game Stats'!$A:$J, 3, False), "") -> 0.42857143 | D6: =iferror(1.2*I6+1.1*H6+1.05*G6+1*F6, "") -> 18.592857 | E6: =iferror(vlookup($A6, 'Player Game Stats'!$A:$J, 4, False), "") -> 17.857143 | F6: =iferror(vlookup($A6, 'Player Game Stats'!$A:$J, 5, False), "") -> 10.714286 | G6: =iferror(vlookup($A6, 'Player Game Stats'!$A:$J, 6, False), "") -> 0.71428571 | H6: =iferror(vlookup($A6, 'Player Game Stats'!$A:$J, 7, False), "") -> 5.8571429 | I6: =IFERROR(vlookup($A6, 'Player Game Stats'!$A:$J, 8, False), "") -> 0.57142857 | J6: =iferror(vlookup($A6, 'Player Game Stats'!$A:$J, 9, False), "") -> 26.142857 | K6: =iferror(vlookup($A6, 'Player Game Stats'!$A:$J, 10, False), "") -> 0.40584416 | L6: =K6*D6 -> 7.5458024 | M6: =iferror(L6*$L$75, "") -> 19.441222
A7: =Draft!B52 -> Somil | B7: =iferror(vlookup($A7, 'Player Game Stats'!$A:$J, 2, False), "") -> 4 | C7: =iferror(vlookup($A7, 'Player Game Stats'!$A:$J, 3, False), "") -> 0.25 | D7: =iferror(1.2*I7+1.1*H7+1.05*G7+1*F7, "") -> 15.8875 | E7: =iferror(vlookup($A7, 'Player Game Stats'!$A:$J, 4, False), "") -> 15.25 | F7: =iferror(vlookup($A7, 'Player Game Stats'!$A:$J, 5, False), "") -> 8.5 | G7: =iferror(vlookup($A7, 'Player Game Stats'!$A:$J, 6, False), "") -> 0.75 | H7: =iferror(vlookup($A7, 'Player Game Stats'!$A:$J, 7, False), "") -> 6 | I7: =IFERROR(vlookup($A7, 'Player Game Stats'!$A:$J, 8, False), "") -> 0 | J7: =iferror(vlookup($A7, 'Player Game Stats'!$A:$J, 9, False), "") -> 27.5 | K7: =iferror(vlookup($A7, 'Player Game Stats'!$A:$J, 10, False), "") -> 0.35672515 | L7: =K7*D7 -> 5.6674708 | M7: =iferror(L7*$L$75, "") -> 14.601835
A8: =Draft!B53 -> Vishal | B8: =iferror(vlookup($A8, 'Player Game Stats'!$A:$J, 2, False), "") -> 5 | C8: =iferror(vlookup($A8, 'Player Game Stats'!$A:$J, 3, False), "") -> 0.6 | D8: =iferror(1.2*I8+1.1*H8+1.05*G8+1*F8, "") -> 18.66 | E8: =iferror(vlookup($A8, 'Player Game Stats'!$A:$J, 4, False), "") -> 17.6 | F8: =iferror(vlookup($A8, 'Player Game Stats'!$A:$J, 5, False), "") -> 7.2 | G8: =iferror(vlookup($A8, 'Player Game Stats'!$A:$J, 6, False), "") -> 2.4 | H8: =iferror(vlookup($A8, 'Player Game Stats'!$A:$J, 7, False), "") -> 6.6 | I8: =IFERROR(vlookup($A8, 'Player Game Stats'!$A:$J, 8, False), "") -> 1.4 | J8: =iferror(vlookup($A8, 'Player Game Stats'!$A:$J, 9, False), "") -> 23 | K8: =iferror(vlookup($A8, 'Player Game Stats'!$A:$J, 10, False), "") -> 0.43349754 | L8: =K8*D8 -> 8.089064 | M8: =iferror(L8*$L$75, "") -> 20.840897
A9: =Draft!B54 -> Sam Ram | B9: =iferror(vlookup($A9, 'Player Game Stats'!$A:$J, 2, False), "") -> 0 | C9: =iferror(vlookup($A9, 'Player Game Stats'!$A:$J, 3, False), "") | D9: =iferror(1.2*I9+1.1*H9+1.05*G9+1*F9, "") -> 0 | E9: =iferror(vlookup($A9, 'Player Game Stats'!$A:$J, 4, False), "") | F9: =iferror(vlookup($A9, 'Player Game Stats'!$A:$J, 5, False), "") | G9: =iferror(vlookup($A9, 'Player Game Stats'!$A:$J, 6, False), "") | H9: =iferror(vlookup($A9, 'Player Game Stats'!$A:$J, 7, False), "") | I9: =IFERROR(vlookup($A9, 'Player Game Stats'!$A:$J, 8, False), "") | J9: =iferror(vlookup($A9, 'Player Game Stats'!$A:$J, 9, False), "") | K9: =iferror(vlookup($A9, 'Player Game Stats'!$A:$J, 10, False), "") | L9: =K9*D9 -> 0 | M9: =iferror(L9*$L$75, "") -> 0
A10: =Draft!B55 -> Chubbs | B10: =iferror(vlookup($A10, 'Player Game Stats'!$A:$J, 2, False), "") -> 0 | C10: =iferror(vlookup($A10, 'Player Game Stats'!$A:$J, 3, False), "") | D10: =iferror(1.2*I10+1.1*H10+1.05*G10+1*F10, "") -> 0 | E10: =iferror(vlookup($A10, 'Player Game Stats'!$A:$J, 4, False), "") | F10: =iferror(vlookup($A10, 'Player Game Stats'!$A:$J, 5, False), "") | G10: =iferror(vlookup($A10, 'Player Game Stats'!$A:$J, 6, False), "") | H10: =iferror(vlookup($A10, 'Player Game Stats'!$A:$J, 7, False), "") | I10: =IFERROR(vlookup($A10, 'Player Game Stats'!$A:$J, 8, False), "") | J10: =iferror(vlookup($A10, 'Player Game Stats'!$A:$J, 9, False), "") | K10: =iferror(vlookup($A10, 'Player Game Stats'!$A:$J, 10, False), "") | L10: =K10*D10 -> 0 | M10: =iferror(L10*$L$75, "") -> 0
A11: =Draft!B56 -> Daniel Mas | B11: =iferror(vlookup($A11, 'Player Game Stats'!$A:$J, 2, False), "") -> 0 | C11: =iferror(vlookup($A11, 'Player Game Stats'!$A:$J, 3, False), "") | D11: =iferror(1.2*I11+1.1*H11+1.05*G11+1*F11, "") -> 0 | E11: =iferror(vlookup($A11, 'Player Game Stats'!$A:$J, 4, False), "") | F11: =iferror(vlookup($A11, 'Player Game Stats'!$A:$J, 5, False), "") | G11: =iferror(vlookup($A11, 'Player Game Stats'!$A:$J, 6, False), "") | H11: =iferror(vlookup($A11, 'Player Game Stats'!$A:$J, 7, False), "") | I11: =IFERROR(vlookup($A11, 'Player Game Stats'!$A:$J, 8, False), "") | J11: =iferror(vlookup($A11, 'Player Game Stats'!$A:$J, 9, False), "") | K11: =iferror(vlookup($A11, 'Player Game Stats'!$A:$J, 10, False), "") | L11: =K11*D11 -> 0 | M11: =iferror(L11*$L$75, "") -> 0
A12: =Draft!B57 | B12: =iferror(vlookup($A12, 'Player Game Stats'!$A:$J, 2, False), "") | C12: =iferror(vlookup($A12, 'Player Game Stats'!$A:$J, 3, False), "") | D12: =iferror(1.2*I12+1.1*H12+1.05*G12+1*F12, "") -> 0 | E12: =iferror(vlookup($A12, 'Player Game Stats'!$A:$J, 4, False), "") | F12: =iferror(vlookup($A12, 'Player Game Stats'!$A:$J, 5, False), "") | G12: =iferror(vlookup($A12, 'Player Game Stats'!$A:$J, 6, False), "") | H12: =iferror(vlookup($A12, 'Player Game Stats'!$A:$J, 7, False), "") | I12: =IFERROR(vlookup($A12, 'Player Game Stats'!$A:$J, 8, False), "") | J12: =iferror(vlookup($A12, 'Player Game Stats'!$A:$J, 9, False), "") | K12: =iferror(vlookup($A12, 'Player Game Stats'!$A:$J, 10, False), "") | L12: =K12*D12 -> 0 | M12: =iferror(L12*$L$75, "") -> 0
